Workbook

Sheet 标题
O6: VERSION 1.0
C18: 3QC全球远程医疗会诊系统
J19: 数据库设计
M29: 3QC
M31: 43180

Sheet 改订历史
A1: 改订历史 | H1: 系统名称 | P1: =标题!C18 -> 3QC全球远程医疗会诊系统 | AK1: 作成日期 | AN1: 43180 | AR1: 作成人员 | AU1: 权
H2: 文档名称 | P2: =标题!J19 -> 数据库设计 | AK2: 修改日期 | AN2: 43180 | AR2: 修改人员 | AU2: 权
A6: No | C6: Ver. | E6: 修改日期 | I6: 修改人员 | M6: 改订内容
A7: =ROW()-6 -> 1 | C7: 1 | E7: 43180 | I7: 权 | M7: 初版作成
A8: =ROW()-6 -> 2
A9: =ROW()-6 -> 3
A10: =ROW()-6 -> 4
A11: =ROW()-6 -> 5
A12: =ROW()-6 -> 6
A13: =ROW()-6 -> 7
A14: =ROW()-6 -> 8
A15: =ROW()-6 -> 9
A16: =ROW()-6 -> 10
A17: =ROW()-6 -> 11
A18: =ROW()-6 -> 12
A19: =ROW()-6 -> 13
... A40: =ROW()-6 -> 34

Sheet 表格列表
A1: 表格列表 | H1: 系统名称 | P1: =标题!C18 -> 3QC全球远程医疗会诊系统 | AK1: 作成日期 | AN1: 43180 | AR1: 作成人员 | AU1: 权
H2: 文档名称 | P2: =标题!J19 -> 数据库设计 | AK2: 修改日期 | AR2: 修改人员
AK3: 主表格 | AR3: 日志表格
A6: No. | C6: 论理表格名称 | N6: 物理表格名称 | W6: 作成日期 | AB6: 备注
A7: =ROW()-6 -> 1 | C7: 用户主表格 | N7: m_user | W7: 43180
A8: =ROW()-6 -> 2 | C8: 用户病种主表格 | N8: m_udisease | W8: 43180
A9: =ROW()-6 -> 3 | C9: 用户所属医院主表格 | N9: m_uhospital | W9: 43180
A10: =ROW()-6 -> 4 | C10: 用户精通语言主表格 | N10: m_ulang | W10: 43180
A11: =ROW()-6 -> 5 | C11: 用户权限主表格 | N11: m_priv | W11: 43180
A12: =ROW()-6 -> 6 | C12: 国家主表格 | N12: m_country | W12: 43180
A13: =ROW()-6 -> 7 | C13: 医院主表格 | N13: m_hospital | W13: 43180
A14: =ROW()-6 -> 8 | C14: 医院国家主表格 | N14: m_hcountry | W14: 43180
A15: =ROW()-6 -> 9 | C15: 病种主表格 | N15: m_disease | W15: 43180
A16: =ROW()-6 -> 10 | C16: 病历模板主表格 | N16: m_dtemplate | W16: 43180
A17: =ROW()-6 -> 11 | C17: 语言主表格 | N17: m_language | W17: 43180
A18: =ROW()-6 -> 12 | C18: 广播主表格 | N18: m_notice | W18: 43180
... A36: =ROW()-6 -> 30 | C36: 会话日志表格 | N36: l_session | W36: 43180
A37: =ROW()-6 -> 31
A38: =ROW()-6 -> 32
A39: =ROW()-6 -> 33
A40: =ROW()-6 -> 34
A41: =ROW()-6 -> 35
A42: =ROW()-6 -> 36
A43: =ROW()-6 -> 37
A44: =ROW()-6 -> 38
A45: =ROW()-6 -> 39

Sheet 用户
A1: 表格 | H1: 系统名称 | P1: =标题!C18 -> 3QC全球远程医疗会诊系统 | AK1: 作成日期 | AN1: 43179 | AR1: 作成人员 | AU1: 权
H2: 文档名称 | P2: =标题!J19 -> 数据库设计 | AK2: 修改日期 | AR2: 修改人员 | AU2: 权
H3: 论理表格名称 | P3: 用户主表格 | AK3: 主键 | AR3: 外键
H4: 物理表格名称 | P4: m_user | AK4: 维护用
A6: No. | C6: 字段名称 | J6: 英文字段名称 | R6: 类型 | W6: 大小 | Y6: 主键 | Z6: 索引 | AA6: 必须 | AC6: 初始值 | AF6: 外键 | AN6: 备注
AF7: 表格名称 | AJ7: 英文字段名称
A8: =IF(C8="", "", MAX($A$1:B7) +1) -> 1 | C8: 编号 | J8: user_id | R8: bigint | Y8: 1 | AA8: ●
A9: =IF(C9="", "", MAX($A$1:B8) +1) -> 2 | C9: 姓名 | J9: user_name | R9: varchar | W9: 50 | AA9: ●
A10: =IF(C10="", "", MAX($A$1:B9) +1) -> 3 | C10: 用户类型 | J10: user_type | R10: decimal | W10: 2 | Z10: I | AA10: ● | AN10: 1：超级管理员，2：普通管理员，16：患者，32：专家，64：翻译人员
A11: =IF(C11="", "", MAX($A$1:B10) +1) -> 4 | C11: 密码 | J11: password | R11: varchar | W11: 40 | AA11: ● | AN11: SHA1散列
A12: =IF(C12="", "", MAX($A$1:B11) +1) -> 5 | C12: 国家编号 | J12: country_id | R12: int | AF12: m_country | AJ12: country_id
A13: =IF(C13="", "", MAX($A$1:B12) +1) -> 6 | C13: 性别 | J13: sex | R13: decimal | W13: 1 | AN13: 0：男 1：女
A14: =IF(C14="", "", MAX($A$1:B13) +1) -> 7 | C14: 电子邮箱 | J14: email | R14: varchar | W14: 80
A15: =IF(C15="", "", MAX($A$1:B14) +1) -> 8 | C15: 手机号码 | J15: mobile | R15: varchar | W15: 25 | AA15: ●
A16: =IF(C16="", "", MAX($A$1:B15) +1) -> 9 | C16: 紧急联系方式 | J16: other_tel | R16: varchar | W16: 25
A17: =IF(C17="", "", MAX($A$1:B16) +1) -> 10 | C17: 家庭住址 | J17: home_address | R17: varchar | W17: 255
A18: =IF(C18="", "", MAX($A$1:B17) +1) -> 11 | C18: 简介 | J18: introduction | R18: varchar | W18: 511
A19: =IF(C19="", "", MAX($A$1:B18) +1) -> 12 | C19: 专家-职称 | J19: d_title | R19: varchar | W19: 255
A20: =IF(C20="", "", MAX($A$1:B19) +1) -> 13 | C20: 专家-所属科室 | J20: d_depart | R20: varchar | W20: 255
A21: =IF(C21="", "", MAX($A$1:B20) +1) -> 14 | C21: 专家-会诊费 | J21: d_fee | R21: decimal | W21: 10,2
A22: =IF(C22="", "", MAX($A$1:B21) +1) -> 15 | C22: 专家-会诊费货币单位 | J22: d_cunit | R22: varchar | W22: 3 | AN22: rmb：人民币 usd：美元
A23: =IF(C23="", "", MAX($A$1:B22) +1) -> 16 | C23: 翻译人员-译龄 | J23: i_age | R23: int
A24: =IF(C24="", "", MAX($A$1:B23) +1) -> 17 | C24: 资格证书 | J24: diplomas | R24: varchar | W24: 255
A25: =IF(C25="", "", MAX($A$1:B24) +1) -> 18 | C25: 身份证件 | J25: passports | R25: varchar | W25: 255
A26: =IF(C26="", "", MAX($A$1:B25) +1) -> 19 | C26: 管理员权限 | J26: admin_priv | R26: varchar | W26: 255
A27: =IF(C27="", "", MAX($A$1:B26) +1) -> 20 | C27: 登录失败数 | J27: login_fails | R27: decimal | W27: 2
A28: =IF(C28="", "", MAX($A$1:B27) +1) -> 21 | C28: 登录锁定标志 | J28: lock_flg | R28: decimal | W28: 1
A29: =IF(C29="", "", MAX($A$1:B28) +1)
A30: =IF(C30="", "", MAX($A$1:B29) +1)
A31: =IF(C31="", "", MAX($A$1:B30) +1)
A32: =IF(C32="", "", MAX($A$1:B31) +1)
A33: =IF(C33="", "", MAX($A$1:B32) +1)
A34: =IF(C34="", "", MAX($A$1:B33) +1)
A35: =IF(C35="", "", MAX($A$1:B34) +1)
A36: =IF(C36="", "", MAX($A$1:B35) +1) -> 22 | C36: 最近访问时刻 | J36: access_time | R36: timestamp
A37: =IF(C37="", "", MAX($A$1:B36) +1) -> 23 | C37: 创建时刻 | J37: create_time | R37: timestamp | AA37: ●
A38: =IF(C38="", "", MAX($A$1:B37) +1) -> 24 | C38: 创建人员 | J38: create_user_id | R38: bigint
A39: =IF(C39="", "", MAX($A$1:B38) +1) -> 25 | C39: 修改时刻 | J39: update_time | R39: timestamp
A40: =IF(C40="", "", MAX($A$1:B39) +1) -> 26 | C40: 修改人员 | J40: update_user_id | R40: bigint
A41: =IF(C41="", "", MAX($A$1:B40) +1) -> 27 | C41: 删除标志 | J41: del_flag | R41: int | W41: 1 | Z41: I | AA41: ● | AC41: 0 | AN41: 0: 未删除，1：删除

Sheet 用户病种
A1: 表格 | H1: 系统名称 | P1: =标题!C18 -> 3QC全球远程医疗会诊系统 | AK1: 作成日期 | AN1: 43179 | AR1: 作成人员 | AU1: 权
H2: 文档名称 | P2: =标题!J19 -> 数据库设计 | AK2: 修改日期 | AR2: 修改人员 | AU2: 权
H3: 论理表格名称 | P3: 用户病种主表格 | AK3: 主键 | AR3: 外键
H4: 物理表格名称 | P4: m_udisease | AK4: 维护用
A6: No. | C6: 字段名称 | J6: 英文字段名称 | R6: 类型 | W6: 大小 | Y6: 主键 | Z6: 索引 | AA6: 必须 | AC6: 初始值 | AF6: 外键 | AN6: 备注
AF7: 表格名称 | AJ7: 英文字段名称
A8: =IF(C8="", "", MAX($A$1:B7) +1) -> 1 | C8: 编号 | J8: udisease_id | R8: bigint | Y8: 1 | AA8: ● | AN8: 自动递增
A9: =IF(C9="", "", MAX($A$1:B8) +1) -> 2 | C9: 用户编号 | J9: user_id | R9: bigint | Z9: I | AA9: ● | AF9: m_user | AJ9: user_id
A10: =IF(C10="", "", MAX($A$1:B9) +1) -> 3 | C10: 病种编号 | J10: disease_id | R10: int | Z10: I | AA10: ● | AF10: m_disease | AJ10: disease_id | AN10: 专家疾病专长
A11: =IF(C11="", "", MAX($A$1:B10) +1)
A12: =IF(C12="", "", MAX($A$1:B11) +1)
A13: =IF(C13="", "", MAX($A$1:B12) +1)
A14: =IF(C14="", "", MAX($A$1:B13) +1)
A15: =IF(C15="", "", MAX($A$1:B14) +1)
A16: =IF(C16="", "", MAX($A$1:B15) +1)
A17: =IF(C17="", "", MAX($A$1:B16) +1)
A18: =IF(C18="", "", MAX($A$1:B17) +1)
A19: =IF(C19="", "", MAX($A$1:B18) +1)
A20: =IF(C20="", "", MAX($A$1:B19) +1)
A21: =IF(C21="", "", MAX($A$1:B20) +1)
A22: =IF(C22="", "", MAX($A$1:B21) +1)
... A32: =IF(C32="", "", MAX($A$1:B31) +1)
A33: =IF(C33="", "", MAX($A$1:B32) +1) -> 4 | C33: 创建时刻 | J33: create_time | R33: timestamp | AA33: ●
A34: =IF(C34="", "", MAX($A$1:B33) +1) -> 5 | C34: 创建人员 | J34: create_user_id | R34: bigint
A35: =IF(C35="", "", MAX($A$1:B34) +1) -> 6 | C35: 修改时刻 | J35: update_time | R35: timestamp
A36: =IF(C36="", "", MAX($A$1:B35) +1) -> 7 | C36: 修改人员 | J36: update_user_id | R36: bigint
A37: =IF(C37="", "", MAX($A$1:B36) +1) -> 8 | C37: 删除标志 | J37: del_flag | R37: int | W37: 1 | Z37: I | AA37: ● | AC37: 0 | AN37: 0: 未删除，1：删除

Sheet 用户所属医院
A1: 表格 | H1: 系统名称 | P1: =标题!C18 -> 3QC全球远程医疗会诊系统 | AK1: 作成日期 | AN1: 43179 | AR1: 作成人员 | AU1: 权
H2: 文档名称 | P2: =标题!J19 -> 数据库设计 | AK2: 修改日期 | AR2: 修改人员 | AU2: 权
H3: 论理表格名称 | P3: 用户所属医院主表格 | AK3: 主键 | AR3: 外键
H4: 物理表格名称 | P4: m_uhospital | AK4: 维护用
A6: No. | C6: 字段名称 | J6: 英文字段名称 | R6: 类型 | W6: 大小 | Y6: 主键 | Z6: 索引 | AA6: 必须 | AC6: 初始值 | AF6: 外键 | AN6: 备注
AF7: 表格名称 | AJ7: 英文字段名称
A8: =IF(C8="", "", MAX($A$1:B7) +1) -> 1 | C8: 编号 | J8: uhospital_id | R8: bigint | Y8: 1 | AA8: ● | AN8: 自动递增
A9: =IF(C9="", "", MAX($A$1:B8) +1) -> 2 | C9: 用户编号 | J9: user_id | R9: bigint | Z9: I | AA9: ● | AF9: m_user | AJ9: user_id
A10: =IF(C10="", "", MAX($A$1:B9) +1) -> 3 | C10: 医院编号 | J10: hospital_id | R10: int | Z10: I | AA10: ● | AF10: m_hospital | AJ10: hospial_id
A11: =IF(C11="", "", MAX($A$1:B10) +1)
A12: =IF(C12="", "", MAX($A$1:B11) +1)
A13: =IF(C13="", "", MAX($A$1:B12) +1)
A14: =IF(C14="", "", MAX($A$1:B13) +1)
A15: =IF(C15="", "", MAX($A$1:B14) +1)
A16: =IF(C16="", "", MAX($A$1:B15) +1)
A17: =IF(C17="", "", MAX($A$1:B16) +1)
A18: =IF(C18="", "", MAX($A$1:B17) +1)
A19: =IF(C19="", "", MAX($A$1:B18) +1)
A20: =IF(C20="", "", MAX($A$1:B19) +1)
A21: =IF(C21="", "", MAX($A$1:B20) +1)
A22: =IF(C22="", "", MAX($A$1:B21) +1)
... A32: =IF(C32="", "", MAX($A$1:B31) +1)
A33: =IF(C33="", "", MAX($A$1:B32) +1) -> 4 | C33: 创建时刻 | J33: create_time | R33: timestamp | AA33: ●
A34: =IF(C34="", "", MAX($A$1:B33) +1) -> 5 | C34: 创建人员 | J34: create_user_id | R34: bigint
A35: =IF(C35="", "", MAX($A$1:B34) +1) -> 6 | C35: 修改时刻 | J35: update_time | R35: timestamp
A36: =IF(C36="", "", MAX($A$1:B35) +1) -> 7 | C36: 修改人员 | J36: update_user_id | R36: bigint
A37: =IF(C37="", "", MAX($A$1:B36) +1) -> 8 | C37: 删除标志 | J37: del_flag | R37: int | W37: 1 | Z37: I | AA37: ● | AC37: 0 | AN37: 0: 未删除，1：删除

Sheet 用户精通语言
A1: 表格 | H1: 系统名称 | P1: =标题!C18 -> 3QC全球远程医疗会诊系统 | AK1: 作成日期 | AN1: 43179 | AR1: 作成人员 | AU1: 权
H2: 文档名称 | P2: =标题!J19 -> 数据库设计 | AK2: 修改日期 | AR2: 修改人员 | AU2: 权
H3: 论理表格名称 | P3: 用户精通语言主表格 | AK3: 主键 | AR3: 外键
H4: 物理表格名称 | P4: m_ulang | AK4: 维护用
A6: No. | C6: 字段名称 | J6: 英文字段名称 | R6: 类型 | W6: 大小 | Y6: 主键 | Z6: 索引 | AA6: 必须 | AC6: 初始值 | AF6: 外键 | AN6: 备注
AF7: 表格名称 | AJ7: 英文字段名称
A8: =IF(C8="", "", MAX($A$1:B7) +1) -> 1 | C8: 编号 | J8: ulang_id | R8: bigint | Y8: 1 | AA8: ● | AN8: 自动递增
A9: =IF(C9="", "", MAX($A$1:B8) +1) -> 2 | C9: 用户编号 | J9: user_id | R9: bigint | Z9: I | AA9: ● | AF9: m_user | AJ9: user_id
A10: =IF(C10="", "", MAX($A$1:B9) +1) -> 3 | C10: 语言编号 | J10: language_id | R10: int | Z10: I | AA10: ● | AF10: m_language | AJ10: language_id
A11: =IF(C11="", "", MAX($A$1:B10) +1)
A12: =IF(C12="", "", MAX($A$1:B11) +1)
A13: =IF(C13="", "", MAX($A$1:B12) +1)
A14: =IF(C14="", "", MAX($A$1:B13) +1)
A15: =IF(C15="", "", MAX($A$1:B14) +1)
A16: =IF(C16="", "", MAX($A$1:B15) +1)
A17: =IF(C17="", "", MAX($A$1:B16) +1)
A18: =IF(C18="", "", MAX($A$1:B17) +1)
A19: =IF(C19="", "", MAX($A$1:B18) +1)
A20: =IF(C20="", "", MAX($A$1:B19) +1)
A21: =IF(C21="", "", MAX($A$1:B20) +1)
A22: =IF(C22="", "", MAX($A$1:B21) +1)
... A32: =IF(C32="", "", MAX($A$1:B31) +1)
A33: =IF(C33="", "", MAX($A$1:B32) +1) -> 4 | C33: 创建时刻 | J33: create_time | R33: timestamp | AA33: ●
A34: =IF(C34="", "", MAX($A$1:B33) +1) -> 5 | C34: 创建人员 | J34: create_user_id | R34: bigint
A35: =IF(C35="", "", MAX($A$1:B34) +1) -> 6 | C35: 修改时刻 | J35: update_time | R35: timestamp
A36: =IF(C36="", "", MAX($A$1:B35) +1) -> 7 | C36: 修改人员 | J36: update_user_id | R36: bigint
A37: =IF(C37="", "", MAX($A$1:B36) +1) -> 8 | C37: 删除标志 | J37: del_flag | R37: int | W37: 1 | Z37: I | AA37: ● | AC37: 0 | AN37: 0: 未删除，1：删除

Sheet 用户权限
A1: 表格 | H1: 系统名称 | P1: =标题!C18 -> 3QC全球远程医疗会诊系统 | AK1: 作成日期 | AN1: 43179 | AR1: 作成人员 | AU1: 权
H2: 文档名称 | P2: =标题!J19 -> 数据库设计 | AK2: 修改日期 | AR2: 修改人员 | AU2: 权
H3: 论理表格名称 | P3: 用户权限主表格 | AK3: 主键 | AR3: 外键
H4: 物理表格名称 | P4: m_priv | AK4: 维护用
A6: No. | C6: 字段名称 | J6: 英文字段名称 | R6: 类型 | W6: 大小 | Y6: 主键 | Z6: 索引 | AA6: 必须 | AC6: 初始值 | AF6: 外键 | AN6: 备注
AF7: 表格名称 | AJ7: 英文字段名称
A8: =IF(C8="", "", MAX($A$1:B7) +1) -> 1 | C8: 编号 | J8: priv_id | R8: int | Y8: 1 | AA8: ● | AN8: 自动递增
A9: =IF(C9="", "", MAX($A$1:B8) +1) -> 2 | C9: 用户编号 | J9: user_id | R9: bigint | Z9: I | AA9: ● | AF9: m_user | AJ9: user_id
A10: =IF(C10="", "", MAX($A$1:B9) +1) -> 3 | C10: 审核注册用户 | J10: priv_reg_user | R10: int
A11: =IF(C11="", "", MAX($A$1:B10) +1) -> 4 | C11: 患者管理 | J11: priv_patients | R11: int
A12: =IF(C12="", "", MAX($A$1:B11) +1) -> 5 | C12: 专家管理 | J12: priv_doctors | R12: int
A13: =IF(C13="", "", MAX($A$1:B12) +1) -> 6 | C13: 翻译管理 | J13: priv_interpreters | R13: int
A14: =IF(C14="", "", MAX($A$1:B13) +1) -> 7 | C14: 医院管理 | J14: priv_hospitals | R14: int
A15: =IF(C15="", "", MAX($A$1:B14) +1) -> 8 | C15: 病历管理 | J15: priv_chistory | R15: int
A16: =IF(C16="", "", MAX($A$1:B15) +1) -> 9 | C16: 会诊预约 | J16: priv_reserve | R16: int
A17: =IF(C17="", "", MAX($A$1:B16) +1) -> 10 | C17: 会诊管理 | J17: priv_interviews | R17: int
A18: =IF(C18="", "", MAX($A$1:B17) +1) -> 11 | C18: 用户信息 | J18: priv_profile | R18: int
A19: =IF(C19="", "", MAX($A$1:B18) +1) -> 12 | C19: 统计分析 | J19: priv_stats | R19: int
A20: =IF(C20="", "", MAX($A$1:B19) +1) -> 13 | C20: 用户反馈 | J20: priv_feedback | R20: int
A21: =IF(C21="", "", MAX($A$1:B20) +1)
A22: =IF(C22="", "", MAX($A$1:B21) +1)
A23: =IF(C23="", "", MAX($A$1:B22) +1)
A24: =IF(C24="", "", MAX($A$1:B23) +1)
A25: =IF(C25="", "", MAX($A$1:B24) +1)
A26: =IF(C26="", "", MAX($A$1:B25) +1)
A27: =IF(C27="", "", MAX($A$1:B26) +1)
A28: =IF(C28="", "", MAX($A$1:B27) +1)
A29: =IF(C29="", "", MAX($A$1:B28) +1)
A30: =IF(C30="", "", MAX($A$1:B29) +1)
A31: =IF(C31="", "", MAX($A$1:B30) +1)
A32: =IF(C32="", "", MAX($A$1:B31) +1)
A33: =IF(C33="", "", MAX($A$1:B32) +1) -> 14 | C33: 创建时刻 | J33: create_time | R33: timestamp | AA33: ●
A34: =IF(C34="", "", MAX($A$1:B33) +1) -> 15 | C34: 创建人员 | J34: create_user_id | R34: bigint
A35: =IF(C35="", "", MAX($A$1:B34) +1) -> 16 | C35: 修改时刻 | J35: update_time | R35: timestamp
A36: =IF(C36="", "", MAX($A$1:B35) +1) -> 17 | C36: 修改人员 | J36: update_user_id | R36: bigint
A37: =IF(C37="", "", MAX($A$1:B36) +1) -> 18 | C37: 删除标志 | J37: del_flag | R37: int | W37: 1 | Z37: I | AA37: ● | AC37: 0 | AN37: 0: 未删除，1：删除

Sheet 国家
A1: 表格 | H1: 系统名称 | P1: =标题!C18 -> 3QC全球远程医疗会诊系统 | AK1: 作成日期 | AN1: 43179 | AR1: 作成人员 | AU1: 权
H2: 文档名称 | P2: =标题!J19 -> 数据库设计 | AK2: 修改日期 | AR2: 修改人员 | AU2: 权
H3: 论理表格名称 | P3: 国家主表格 | AK3: 主键 | AR3: 外键
H4: 物理表格名称 | P4: m_country | AK4: 维护用
A6: No. | C6: 字段名称 | J6: 英文字段名称 | R6: 类型 | W6: 大小 | Y6: 主键 | Z6: 索引 | AA6: 必须 | AC6: 初始值 | AF6: 外键 | AN6: 备注
AF7: 表格名称 | AJ7: 英文字段名称
A8: =IF(C8="", "", MAX($A$1:B7) +1) -> 1 | C8: 编号 | J8: country_id | R8: bigint | Y8: 1 | AA8: ● | AN8: 自动递增
A9: =IF(C9="", "", MAX($A$1:B8) +1) -> 2 | C9: 国家名称 | J9: country_name | R9: varchar | W9: 50 | AA9: ●
A10: =IF(C10="", "", MAX($A$1:B9) +1) -> 3 | C10: 国家码 | J10: country_code | R10: varchar | W10: 4
A11: =IF(C11="", "", MAX($A$1:B10) +1) -> 4 | C11: 国际区号 | J11: dial_code | R11: varchar | W11: 5 | Z11: I
A12: =IF(C12="", "", MAX($A$1:B11) +1) -> 5 | C12: 国际区号次序 | J12: dial_code_order | R12: int | Z12: I
A13: =IF(C13="", "", MAX($A$1:B12) +1) -> 6 | C13: 部分国际区号 | J13: sub_dial_codes | R13: text
A14: =IF(C14="", "", MAX($A$1:B13) +1)
A15: =IF(C15="", "", MAX($A$1:B14) +1)
A16: =IF(C16="", "", MAX($A$1:B15) +1)
A17: =IF(C17="", "", MAX($A$1:B16) +1)
A18: =IF(C18="", "", MAX($A$1:B17) +1)
A19: =IF(C19="", "", MAX($A$1:B18) +1)
A20: =IF(C20="", "", MAX($A$1:B19) +1)
A21: =IF(C21="", "", MAX($A$1:B20) +1)
A22: =IF(C22="", "", MAX($A$1:B21) +1)
A23: =IF(C23="", "", MAX($A$1:B22) +1)
A24: =IF(C24="", "", MAX($A$1:B23) +1)
A25: =IF(C25="", "", MAX($A$1:B24) +1)
... A33: =IF(C33="", "", MAX($A$1:B32) +1)
A34: =IF(C34="", "", MAX($A$1:B33) +1) -> 7 | C34: 创建时刻 | J34: create_time | R34: timestamp | AA34: ●
A35: =IF(C35="", "", MAX($A$1:B34) +1) -> 8 | C35: 修改时刻 | J35: update_time | R35: timestamp

Sheet 医院
A1: 表格 | H1: 系统名称 | P1: =标题!C18 -> 3QC全球远程医疗会诊系统 | AK1: 作成日期 | AN1: 43179 | AR1: 作成人员 | AU1: 权
H2: 文档名称 | P2: =标题!J19 -> 数据库设计 | AK2: 修改日期 | AR2: 修改人员 | AU2: 权
H3: 论理表格名称 | P3: 医院主表格 | AK3: 主键 | AR3: 外键
H4: 物理表格名称 | P4: m_hospital | AK4: 维护用
A6: No. | C6: 字段名称 | J6: 英文字段名称 | R6: 类型 | W6: 大小 | Y6: 主键 | Z6: 索引 | AA6: 必须 | AC6: 初始值 | AF6: 外键 | AN6: 备注
AF7: 表格名称 | AJ7: 英文字段名称
A8: =IF(C8="", "", MAX($A$1:B7) +1) -> 1 | C8: 编号 | J8: hospital_id | R8: int | Y8: 1 | AA8: ● | AN8: 自动递增
A9: =IF(C9="", "", MAX($A$1:B8) +1) -> 2 | C9: 医院国家编号 | J9: hcountry_id | R9: int | AF9: m_hcountry | AJ9: hcountry_id
A10: =IF(C10="", "", MAX($A$1:B9) +1) -> 3 | C10: 医院名称 | J10: hospital_name | R10: varchar | W10: 50 | AA10: ●
A11: =IF(C11="", "", MAX($A$1:B10) +1) -> 4 | C11: 医院名称(多语言） | J11: hospital_name_l | R11: text | AN11: json字符串
A12: =IF(C12="", "", MAX($A$1:B11) +1) -> 5 | C12: 医院地址 | J12: address | R12: varchar | W12: 255
A13: =IF(C13="", "", MAX($A$1:B12) +1) -> 6 | C13: 显示次序 | J13: sort | R13: int
A14: =IF(C14="", "", MAX($A$1:B13) +1)
A15: =IF(C15="", "", MAX($A$1:B14) +1)
A16: =IF(C16="", "", MAX($A$1:B15) +1)
A17: =IF(C17="", "", MAX($A$1:B16) +1)
A18: =IF(C18="", "", MAX($A$1:B17) +1)
A19: =IF(C19="", "", MAX($A$1:B18) +1)
A20: =IF(C20="", "", MAX($A$1:B19) +1)
A21: =IF(C21="", "", MAX($A$1:B20) +1)
A22: =IF(C22="", "", MAX($A$1:B21) +1)
A23: =IF(C23="", "", MAX($A$1:B22) +1)
A24: =IF(C24="", "", MAX($A$1:B23) +1)
A25: =IF(C25="", "", MAX($A$1:B24) +1)
... A33: =IF(C33="", "", MAX($A$1:B32) +1)
A34: =IF(C34="", "", MAX($A$1:B33) +1) -> 7 | C34: 创建时刻 | J34: create_time | R34: timestamp | AA34: ●
A35: =IF(C35="", "", MAX($A$1:B34) +1) -> 8 | C35: 创建人员 | J35: create_user_id | R35: bigint
A36: =IF(C36="", "", MAX($A$1:B35) +1) -> 9 | C36: 修改时刻 | J36: update_time | R36: timestamp
A37: =IF(C37="", "", MAX($A$1:B36) +1) -> 10 | C37: 修改人员 | J37: update_user_id | R37: bigint
A38: =IF(C38="", "", MAX($A$1:B37) +1) -> 11 | C38: 删除标志 | J38: del_flag | R38: int | W38: 1 | Z38: I | AA38: ● | AC38: 0 | AN38: 0: 未删除，1：删除

Sheet 医院国家
A1: 表格 | H1: 系统名称 | P1: =标题!C18 -> 3QC全球远程医疗会诊系统 | AK1: 作成日期 | AN1: 43179 | AR1: 作成人员 | AU1: 权
H2: 文档名称 | P2: =标题!J19 -> 数据库设计 | AK2: 修改日期 | AR2: 修改人员 | AU2: 权
H3: 论理表格名称 | P3: 医院国家主表格 | AK3: 主键 | AR3: 外键
H4: 物理表格名称 | P4: m_hcountry | AK4: 维护用
A6: No. | C6: 字段名称 | J6: 英文字段名称 | R6: 类型 | W6: 大小 | Y6: 主键 | Z6: 索引 | AA6: 必须 | AC6: 初始值 | AF6: 外键 | AN6: 备注
AF7: 表格名称 | AJ7: 英文字段名称
A8: =IF(C8="", "", MAX($A$1:B7) +1) -> 1 | C8: 编号 | J8: hcountry_id | R8: int | Y8: 1 | AA8: ● | AN8: 自动递增
A9: =IF(C9="", "", MAX($A$1:B8) +1) -> 2 | C9: 医院国家名称 | J9: country_name | R9: varchar | W9: 50 | AA9: ●
A10: =IF(C10="", "", MAX($A$1:B9) +1) -> 3 | C10: 医院国家名称(多语言） | J10: country_name_l | R10: text | AN10: json字符串
A11: =IF(C11="", "", MAX($A$1:B10) +1) -> 4 | C11: 显示次序 | J11: sort | R11: int
A12: =IF(C12="", "", MAX($A$1:B11) +1) -> 5 | C12: 医院展开标志 | J12: h_expand_flag | R12: tinyint | W12: 1
A13: =IF(C13="", "", MAX($A$1:B12) +1)
A14: =IF(C14="", "", MAX($A$1:B13) +1)
A15: =IF(C15="", "", MAX($A$1:B14) +1)
A16: =IF(C16="", "", MAX($A$1:B15) +1)
A17: =IF(C17="", "", MAX($A$1:B16) +1)
A18: =IF(C18="", "", MAX($A$1:B17) +1)
A19: =IF(C19="", "", MAX($A$1:B18) +1)
A20: =IF(C20="", "", MAX($A$1:B19) +1)
A21: =IF(C21="", "", MAX($A$1:B20) +1)
A22: =IF(C22="", "", MAX($A$1:B21) +1)
A23: =IF(C23="", "", MAX($A$1:B22) +1)
A24: =IF(C24="", "", MAX($A$1:B23) +1)
... A31: =IF(C31="", "", MAX($A$1:B30) +1)
A32: =IF(C32="", "", MAX($A$1:B31) +1) -> 6 | C32: 创建时刻 | J32: create_time | R32: timestamp | AA32: ●
A33: =IF(C33="", "", MAX($A$1:B32) +1) -> 7 | C33: 创建人员 | J33: create_user_id | R33: bigint
A34: =IF(C34="", "", MAX($A$1:B33) +1) -> 8 | C34: 修改时刻 | J34: update_time | R34: timestamp
A35: =IF(C35="", "", MAX($A$1:B34) +1) -> 9 | C35: 修改人员 | J35: update_user_id | R35: bigint
A36: =IF(C36="", "", MAX($A$1:B35) +1) -> 10 | C36: 删除标志 | J36: del_flag | R36: int | W36: 1 | Z36: I | AA36: ● | AC36: 0 | AN36: 0: 未删除，1：删除

Sheet 病种
A1: 表格 | H1: 系统名称 | P1: =标题!C18 -> 3QC全球远程医疗会诊系统 | AK1: 作成日期 | AN1: 43179 | AR1: 作成人员 | AU1: 权
H2: 文档名称 | P2: =标题!J19 -> 数据库设计 | AK2: 修改日期 | AR2: 修改人员 | AU2: 权
H3: 论理表格名称 | P3: 病种主表格 | AK3: 主键 | AR3: 外键
H4: 物理表格名称 | P4: m_disease | AK4: 维护用
A6: No. | C6: 字段名称 | J6: 英文字段名称 | R6: 类型 | W6: 大小 | Y6: 主键 | Z6: 索引 | AA6: 必须 | AC6: 初始值 | AF6: 外键 | AN6: 备注
AF7: 表格名称 | AJ7: 英文字段名称
A8: =IF(C8="", "", MAX($A$1:B7) +1) -> 1 | C8: 编号 | J8: disease_id | R8: bigint | Y8: 1 | AA8: ● | AN8: 自动递增
A9: =IF(C9="", "", MAX($A$1:B8) +1) -> 2 | C9: 病种名称 | J9: disease_name | R9: varchar | W9: 50 | AA9: ●
A10: =IF(C10="", "", MAX($A$1:B9) +1) -> 3 | C10: 病种名称(多语言） | J10: disease_name_l | R10: text | AN10: json字符串
A11: =IF(C11="", "", MAX($A$1:B10) +1) -> 4 | C11: 病种简介 | J11: description | R11: text
A12: =IF(C12="", "", MAX($A$1:B11) +1) -> 5 | C12: 显示次序 | J12: sort | R12: int
A13: =IF(C13="", "", MAX($A$1:B12) +1)
A14: =IF(C14="", "", MAX($A$1:B13) +1)
A15: =IF(C15="", "", MAX($A$1:B14) +1)
A16: =IF(C16="", "", MAX($A$1:B15) +1)
A17: =IF(C17="", "", MAX($A$1:B16) +1)
A18: =IF(C18="", "", MAX($A$1:B17) +1)
A19: =IF(C19="", "", MAX($A$1:B18) +1)
A20: =IF(C20="", "", MAX($A$1:B19) +1)
A21: =IF(C21="", "", MAX($A$1:B20) +1)
A22: =IF(C22="", "", MAX($A$1:B21) +1)
A23: =IF(C23="", "", MAX($A$1:B22) +1)
A24: =IF(C24="", "", MAX($A$1:B23) +1)
... A32: =IF(C32="", "", MAX($A$1:B31) +1)
A33: =IF(C33="", "", MAX($A$1:B32) +1) -> 6 | C33: 创建时刻 | J33: create_time | R33: timestamp | AA33: ●
A34: =IF(C34="", "", MAX($A$1:B33) +1) -> 7 | C34: 创建人员 | J34: create_user_id | R34: bigint
A35: =IF(C35="", "", MAX($A$1:B34) +1) -> 8 | C35: 修改时刻 | J35: update_time | R35: timestamp
A36: =IF(C36="", "", MAX($A$1:B35) +1) -> 9 | C36: 修改人员 | J36: update_user_id | R36: bigint
A37: =IF(C37="", "", MAX($A$1:B36) +1) -> 10 | C37: 删除标志 | J37: del_flag | R37: int | W37: 1 | Z37: I | AA37: ● | AC37: 0 | AN37: 0: 未删除，1：删除

Sheet 病历模板
A1: 表格 | H1: 系统名称 | P1: =标题!C18 -> 3QC全球远程医疗会诊系统 | AK1: 作成日期 | AN1: 43179 | AR1: 作成人员 | AU1: 权
H2: 文档名称 | P2: =标题!J19 -> 数据库设计 | AK2: 修改日期 | AR2: 修改人员 | AU2: 权
H3: 论理表格名称 | P3: 病历模板主表格 | AK3: 主键 | AR3: 外键
H4: 物理表格名称 | P4: m_dtemplate | AK4: 维护用
A6: No. | C6: 字段名称 | J6: 英文字段名称 | R6: 类型 | W6: 大小 | Y6: 主键 | Z6: 索引 | AA6: 必须 | AC6: 初始值 | AF6: 外键 | AN6: 备注
AF7: 表格名称 | AJ7: 英文字段名称
A8: =IF(C8="", "", MAX($A$1:B7) +1) -> 1 | C8: 编号 | J8: dtemplate_id | R8: bigint | Y8: 1 | AA8: ● | AN8: 自动递增
A9: =IF(C9="", "", MAX($A$1:B8) +1) -> 2 | C9: 病种编号 | J9: disease_id | R9: int | Z9: I
A10: =IF(C10="", "", MAX($A$1:B9) +1) -> 3 | C10: 模板名称 | J10: dtemplate_name | R10: varchar | W10: 100
A11: =IF(C11="", "", MAX($A$1:B10) +1) -> 4 | C11: 模板名称（多语言） | J11: dtemplate_name_l | R11: text | AN11: json字符串
A12: =IF(C12="", "", MAX($A$1:B11) +1) -> 5 | C12: 显示次序 | J12: sort | R12: int
A13: =IF(C13="", "", MAX($A$1:B12) +1) -> 6 | C13: 模板文件（复数） | J13: template_file | R13: text | AN13: 如果是复数文件，与","组合
A14: =IF(C14="", "", MAX($A$1:B13) +1)
A15: =IF(C15="", "", MAX($A$1:B14) +1)
A16: =IF(C16="", "", MAX($A$1:B15) +1)
A17: =IF(C17="", "", MAX($A$1:B16) +1)
A18: =IF(C18="", "", MAX($A$1:B17) +1)
A19: =IF(C19="", "", MAX($A$1:B18) +1)
A20: =IF(C20="", "", MAX($A$1:B19) +1)
A21: =IF(C21="", "", MAX($A$1:B20) +1)
A22: =IF(C22="", "", MAX($A$1:B21) +1)
A23: =IF(C23="", "", MAX($A$1:B22) +1)
A24: =IF(C24="", "", MAX($A$1:B23) +1)
A25: =IF(C25="", "", MAX($A$1:B24) +1)
... A33: =IF(C33="", "", MAX($A$1:B32) +1)
A34: =IF(C34="", "", MAX($A$1:B33) +1) -> 7 | C34: 创建时刻 | J34: create_time | R34: timestamp | AA34: ●
A35: =IF(C35="", "", MAX($A$1:B34) +1) -> 8 | C35: 创建人员 | J35: create_user_id | R35: bigint
A36: =IF(C36="", "", MAX($A$1:B35) +1) -> 9 | C36: 修改时刻 | J36: update_time | R36: timestamp
A37: =IF(C37="", "", MAX($A$1:B36) +1) -> 10 | C37: 修改人员 | J37: update_user_id | R37: bigint
A38: =IF(C38="", "", MAX($A$1:B37) +1) -> 11 | C38: 删除标志 | J38: del_flag | R38: int | W38: 1 | Z38: I | AA38: ● | AC38: 0 | AN38: 0: 未删除，1：删除

Sheet 语言
A1: 表格 | H1: 系统名称 | P1: =标题!C18 -> 3QC全球远程医疗会诊系统 | AK1: 作成日期 | AN1: 43179 | AR1: 作成人员 | AU1: 权
H2: 文档名称 | P2: =标题!J19 -> 数据库设计 | AK2: 修改日期 | AR2: 修改人员 | AU2: 权
H3: 论理表格名称 | P3: 语言主表格 | AK3: 主键 | AR3: 外键
H4: 物理表格名称 | P4: m_language | AK4: 维护用
A6: No. | C6: 字段名称 | J6: 英文字段名称 | R6: 类型 | W6: 大小 | Y6: 主键 | Z6: 索引 | AA6: 必须 | AC6: 初始值 | AF6: 外键 | AN6: 备注
AF7: 表格名称 | AJ7: 英文字段名称
A8: =IF(C8="", "", MAX($A$1:B7) +1) -> 1 | C8: 编号 | J8: language_id | R8: int | Y8: 1 | AA8: ● | AN8: 自动递增
A9: =IF(C9="", "", MAX($A$1:B8) +1) -> 2 | C9: 语言名称 | J9: language_name | R9: varchar | W9: 50
A10: =IF(C10="", "", MAX($A$1:B9) +1) -> 3 | C10: 语言名称（多语言） | J10: language_name_l | R10: text | AN10: json字符串
A11: =IF(C11="", "", MAX($A$1:B10) +1) -> 4 | C11: 语言代码 | J11: language_code | R11: varchar | W11: 10 | AN11: 例如：汉语：zh-CN 英语：en-US
A12: =IF(C12="", "", MAX($A$1:B11) +1) -> 5 | C12: 显示次序 | J12: sort | R12: int
A13: =IF(C13="", "", MAX($A$1:B12) +1)
A14: =IF(C14="", "", MAX($A$1:B13) +1)
A15: =IF(C15="", "", MAX($A$1:B14) +1)
A16: =IF(C16="", "", MAX($A$1:B15) +1)
A17: =IF(C17="", "", MAX($A$1:B16) +1)
A18: =IF(C18="", "", MAX($A$1:B17) +1)
A19: =IF(C19="", "", MAX($A$1:B18) +1)
A20: =IF(C20="", "", MAX($A$1:B19) +1)
A21: =IF(C21="", "", MAX($A$1:B20) +1)
A22: =IF(C22="", "", MAX($A$1:B21) +1)
A23: =IF(C23="", "", MAX($A$1:B22) +1)
A24: =IF(C24="", "", MAX($A$1:B23) +1)
... A32: =IF(C32="", "", MAX($A$1:B31) +1)
A33: =IF(C33="", "", MAX($A$1:B32) +1) -> 6 | C33: 创建时刻 | J33: create_time | R33: timestamp | AA33: ●
A34: =IF(C34="", "", MAX($A$1:B33) +1) -> 7 | C34: 创建人员 | J34: create_user_id | R34: bigint
A35: =IF(C35="", "", MAX($A$1:B34) +1) -> 8 | C35: 修改时刻 | J35: update_time | R35: timestamp
A36: =IF(C36="", "", MAX($A$1:B35) +1) -> 9 | C36: 修改人员 | J36: update_user_id | R36: bigint
A37: =IF(C37="", "", MAX($A$1:B36) +1) -> 10 | C37: 删除标志 | J37: del_flag | R37: int | W37: 1 | Z37: I | AA37: ● | AC37: 0 | AN37: 0: 未删除，1：删除

Sheet 广播
A1: 表格 | H1: 系统名称 | P1: =标题!C18 -> 3QC全球远程医疗会诊系统 | AK1: 作成日期 | AN1: 43179 | AR1: 作成人员 | AU1: 权
H2: 文档名称 | P2: =标题!J19 -> 数据库设计 | AK2: 修改日期 | AR2: 修改人员 | AU2: 权
H3: 论理表格名称 | P3: 广播主表格 | AK3: 主键 | AR3: 外键
H4: 物理表格名称 | P4: m_notice | AK4: 维护用
A6: No. | C6: 字段名称 | J6: 英文字段名称 | R6: 类型 | W6: 大小 | Y6: 主键 | Z6: 索引 | AA6: 必须 | AC6: 初始值 | AF6: 外键 | AN6: 备注
AF7: 表格名称 | AJ7: 英文字段名称
A8: =IF(C8="", "", MAX($A$1:B7) +1) -> 1 | C8: 编号 | J8: notice_id | R8: int | Y8: 1 | AA8: ● | AN8: 自动递增
A9: =IF(C9="", "", MAX($A$1:B8) +1) -> 2 | C9: 广播内容 | J9: content | R9: varchar | W9: 255
A10: =IF(C10="", "", MAX($A$1:B9) +1) -> 3 | C10: 广播内容（多语言） | J10: content_l | R10: text | AN10: json字符串
A11: =IF(C11="", "", MAX($A$1:B10) +1)
A12: =IF(C12="", "", MAX($A$1:B11) +1)
A13: =IF(C13="", "", MAX($A$1:B12) +1)
A14: =IF(C14="", "", MAX($A$1:B13) +1)
A15: =IF(C15="", "", MAX($A$1:B14) +1)
A16: =IF(C16="", "", MAX($A$1:B15) +1)
A17: =IF(C17="", "", MAX($A$1:B16) +1)
A18: =IF(C18="", "", MAX($A$1:B17) +1)
A19: =IF(C19="", "", MAX($A$1:B18) +1)
A20: =IF(C20="", "", MAX($A$1:B19) +1)
A21: =IF(C21="", "", MAX($A$1:B20) +1)
A22: =IF(C22="", "", MAX($A$1:B21) +1)
... A32: =IF(C32="", "", MAX($A$1:B31) +1)
A33: =IF(C33="", "", MAX($A$1:B32) +1) -> 4 | C33: 创建时刻 | J33: create_time | R33: timestamp | AA33: ●
A34: =IF(C34="", "", MAX($A$1:B33) +1) -> 5 | C34: 创建人员 | J34: create_user_id | R34: bigint
A35: =IF(C35="", "", MAX($A$1:B34) +1) -> 6 | C35: 修改时刻 | J35: update_time | R35: timestamp
A36: =IF(C36="", "", MAX($A$1:B35) +1) -> 7 | C36: 修改人员 | J36: update_user_id | R36: bigint
A37: =IF(C37="", "", MAX($A$1:B36) +1) -> 8 | C37: 删除标志 | J37: del_flag | R37: int | W37: 1 | Z37: I | AA37: ● | AC37: 0 | AN37: 0: 未删除，1：删除

Sheet 汇率
A1: 表格 | H1: 系统名称 | P1: =标题!C18 -> 3QC全球远程医疗会诊系统 | AK1: 作成日期 | AN1: 43179 | AR1: 作成人员 | AU1: 权
H2: 文档名称 | P2: =标题!J19 -> 数据库设计 | AK2: 修改日期 | AR2: 修改人员 | AU2: 权
H3: 论理表格名称 | P3: 汇率主表格 | AK3: 主键 | AR3: 外键
H4: 物理表格名称 | P4: m_exrate | AK4: 维护用
A6: No. | C6: 字段名称 | J6: 英文字段名称 | R6: 类型 | W6: 大小 | Y6: 主键 | Z6: 索引 | AA6: 必须 | AC6: 初始值 | AF6: 外键 | AN6: 备注
AF7: 表格名称 | AJ7: 英文字段名称
A8: =IF(C8="", "", MAX($A$1:B7) +1) -> 1 | C8: 编号 | J8: exrate_id | R8: int | Y8: 1 | AA8: ● | AN8: 自动递增
A9: =IF(C9="", "", MAX($A$1:B8) +1) -> 2 | C9: 更新时刻 | J9: exrate_time | R9: timestamp
A10: =IF(C10="", "", MAX($A$1:B9) +1) -> 3 | C10: 人民币到美元汇率 | J10: rmb_to_usd | R10: decimal | W10: 10,4
A11: =IF(C11="", "", MAX($A$1:B10) +1) -> 4 | C11: 美元到人民币汇率 | J11: usd_to_rmb | R11: decimal | W11: 10,4
A12: =IF(C12="", "", MAX($A$1:B11) +1)
A13: =IF(C13="", "", MAX($A$1:B12) +1)
A14: =IF(C14="", "", MAX($A$1:B13) +1)
A15: =IF(C15="", "", MAX($A$1:B14) +1)
A16: =IF(C16="", "", MAX($A$1:B15) +1)
A17: =IF(C17="", "", MAX($A$1:B16) +1)
A18: =IF(C18="", "", MAX($A$1:B17) +1)
A19: =IF(C19="", "", MAX($A$1:B18) +1)
A20: =IF(C20="", "", MAX($A$1:B19) +1)
A21: =IF(C21="", "", MAX($A$1:B20) +1)
A22: =IF(C22="", "", MAX($A$1:B21) +1)
A23: =IF(C23="", "", MAX($A$1:B22) +1)
... A32: =IF(C32="", "", MAX($A$1:B31) +1)
A33: =IF(C33="", "", MAX($A$1:B32) +1) -> 5 | C33: 创建时刻 | J33: create_time | R33: timestamp | AA33: ●
A34: =IF(C34="", "", MAX($A$1:B33) +1) -> 6 | C34: 创建人员 | J34: create_user_id | R34: bigint
A35: =IF(C35="", "", MAX($A$1:B34) +1) -> 7 | C35: 修改时刻 | J35: update_time | R35: timestamp
A36: =IF(C36="", "", MAX($A$1:B35) +1) -> 8 | C36: 修改人员 | J36: update_user_id | R36: bigint
A37: =IF(C37="", "", MAX($A$1:B36) +1) -> 9 | C37: 删除标志 | J37: del_flag | R37: int | W37: 1 | Z37: I | AA37: ● | AC37: 0 | AN37: 0: 未删除，1：删除

Sheet 字符串
A1: 表格 | H1: 系统名称 | P1: =标题!C18 -> 3QC全球远程医疗会诊系统 | AK1: 作成日期 | AN1: 43179 | AR1: 作成人员 | AU1: 权
H2: 文档名称 | P2: =标题!J19 -> 数据库设计 | AK2: 修改日期 | AR2: 修改人员 | AU2: 权
H3: 论理表格名称 | P3: 字符串主表格 | AK3: 主键 | AR3: 外键
H4: 物理表格名称 | P4: m_string | AK4: 维护用
A6: No. | C6: 字段名称 | J6: 英文字段名称 | R6: 类型 | W6: 大小 | Y6: 主键 | Z6: 索引 | AA6: 必须 | AC6: 初始值 | AF6: 外键 | AN6: 备注
AF7: 表格名称 | AJ7: 英文字段名称
A8: =IF(C8="", "", MAX($A$1:B7) +1) -> 1 | C8: 编号 | J8: string_id | R8: int | Y8: 1 | AA8: ● | AN8: 自动递增
A9: =IF(C9="", "", MAX($A$1:B8) +1) -> 2 | C9: 字符串 | J9: string | R9: varchar | W9: 511
A10: =IF(C10="", "", MAX($A$1:B9) +1) -> 3 | C10: 字符串（多语言） | J10: string_l | R10: text | AN10: json字符串
A11: =IF(C11="", "", MAX($A$1:B10) +1)
A12: =IF(C12="", "", MAX($A$1:B11) +1)
A13: =IF(C13="", "", MAX($A$1:B12) +1)
A14: =IF(C14="", "", MAX($A$1:B13) +1)
A15: =IF(C15="", "", MAX($A$1:B14) +1)
A16: =IF(C16="", "", MAX($A$1:B15) +1)
A17: =IF(C17="", "", MAX($A$1:B16) +1)
A18: =IF(C18="", "", MAX($A$1:B17) +1)
A19: =IF(C19="", "", MAX($A$1:B18) +1)
A20: =IF(C20="", "", MAX($A$1:B19) +1)
A21: =IF(C21="", "", MAX($A$1:B20) +1)
A22: =IF(C22="", "", MAX($A$1:B21) +1)
... A32: =IF(C32="", "", MAX($A$1:B31) +1)
A33: =IF(C33="", "", MAX($A$1:B32) +1) -> 4 | C33: 创建时刻 | J33: create_time | R33: timestamp | AA33: ●
A34: =IF(C34="", "", MAX($A$1:B33) +1) -> 5 | C34: 创建人员 | J34: create_user_id | R34: bigint
A35: =IF(C35="", "", MAX($A$1:B34) +1) -> 6 | C35: 修改时刻 | J35: update_time | R35: timestamp
A36: =IF(C36="", "", MAX($A$1:B35) +1) -> 7 | C36: 修改人员 | J36: update_user_id | R36: bigint
A37: =IF(C37="", "", MAX($A$1:B36) +1) -> 8 | C37: 删除标志 | J37: del_flag | R37: int | W37: 1 | Z37: I | AA37: ● | AC37: 0 | AN37: 0: 未删除，1：删除

Sheet 系统设置
A1: 表格 | H1: 系统名称 | P1: =标题!C18 -> 3QC全球远程医疗会诊系统 | AK1: 作成日期 | AN1: 43179 | AR1: 作成人员 | AU1: 权
H2: 文档名称 | P2: =标题!J19 -> 数据库设计 | AK2: 修改日期 | AR2: 修改人员 | AU2: 权
H3: 论理表格名称 | P3: 系统设置主表格 | AK3: 主键 | AR3: 外键
H4: 物理表格名称 | P4: m_settings | AK4: 维护用
A6: No. | C6: 字段名称 | J6: 英文字段名称 | R6: 类型 | W6: 大小 | Y6: 主键 | Z6: 索引 | AA6: 必须 | AC6: 初始值 | AF6: 外键 | AN6: 备注
AF7: 表格名称 | AJ7: 英文字段名称
A8: =IF(C8="", "", MAX($A$1:B7) +1) -> 1 | C8: 编号 | J8: settings_id | R8: int | Y8: 1 | AA8: ● | AN8: 自动递增
A9: =IF(C9="", "", MAX($A$1:B8) +1) -> 2 | C9: 会诊视频存储时间 (天) | J9: save_record_limit | R9: int | AA9: ●
A10: =IF(C10="", "", MAX($A$1:B9) +1)
A11: =IF(C11="", "", MAX($A$1:B10) +1)
A12: =IF(C12="", "", MAX($A$1:B11) +1)
A13: =IF(C13="", "", MAX($A$1:B12) +1)
A14: =IF(C14="", "", MAX($A$1:B13) +1)
A15: =IF(C15="", "", MAX($A$1:B14) +1)
A16: =IF(C16="", "", MAX($A$1:B15) +1)
A17: =IF(C17="", "", MAX($A$1:B16) +1)
A18: =IF(C18="", "", MAX($A$1:B17) +1)
A19: =IF(C19="", "", MAX($A$1:B18) +1)
A20: =IF(C20="", "", MAX($A$1:B19) +1)
A21: =IF(C21="", "", MAX($A$1:B20) +1)
... A32: =IF(C32="", "", MAX($A$1:B31) +1)
A33: =IF(C33="", "", MAX($A$1:B32) +1) -> 3 | C33: 创建时刻 | J33: create_time | R33: timestamp | AA33: ●
A34: =IF(C34="", "", MAX($A$1:B33) +1) -> 4 | C34: 创建人员 | J34: create_user_id | R34: bigint
A35: =IF(C35="", "", MAX($A$1:B34) +1) -> 5 | C35: 修改时刻 | J35: update_time
A36: =IF(C36="", "", MAX($A$1:B35) +1) -> 6 | C36: 修改人员 | J36: update_user_id | R36: bigint
A37: =IF(C37="", "", MAX($A$1:B36) +1) -> 7 | C37: 删除标志 | J37: del_flag | R37: int | W37: 1 | Z37: I | AA37: ● | AC37: 0 | AN37: 0: 未删除，1：删除

Sheet 病历
A1: 表格 | H1: 系统名称 | P1: =标题!C18 -> 3QC全球远程医疗会诊系统 | AK1: 作成日期 | AN1: 43179 | AR1: 作成人员 | AU1: 权
H2: 文档名称 | P2: =标题!J19 -> 数据库设计 | AK2: 修改日期 | AR2: 修改人员 | AU2: 权
H3: 论理表格名称 | P3: 病历表格 | AK3: 主键 | AR3: 外键
H4: 物理表格名称 | P4: t_chistory | AK4: 维护用
A6: No. | C6: 字段名称 | J6: 英文字段名称 | R6: 类型 | W6: 大小 | Y6: 主键 | Z6: 索引 | AA6: 必须 | AC6: 初始值 | AF6: 外键 | AN6: 备注
AF7: 表格名称 | AJ7: 英文字段名称
A8: =IF(C8="", "", MAX($A$1:B7) +1) -> 1 | C8: 编号 | J8: chistory_id | R8: bigint | Y8: 1 | AA8: ●
A9: =IF(C9="", "", MAX($A$1:B8) +1) -> 2 | C9: 用户编号 | J9: user_id | R9: bigint | Z9: I | AA9: ● | AF9: m_user | AJ9: user_id
A10: =IF(C10="", "", MAX($A$1:B9) +1) -> 3 | C10: 翻译标志 | J10: trans_flag | R10: tinyint | W10: 1 | AA10: ● | AC10: 0 | AN10: 0:原版病历 1：翻译版病历
A11: =IF(C11="", "", MAX($A$1:B10) +1) -> 4 | C11: 会诊编号 | J11: interview_id | R11: bigint | AF11: t_interview | AJ11: interview_id | AN11: 在翻译版病历中，指相关会诊
A12: =IF(C12="", "", MAX($A$1:B11) +1) -> 5 | C12: 原版病历编号 | J12: org_id | R12: bigint | AN12: 只在翻译版病历中
A13: =IF(C13="", "", MAX($A$1:B12) +1) -> 6 | C13: 提交标志 | J13: post_flag | R13: tinyint | W13: 1 | AN13: 0：修改中 1：已提交
A14: =IF(C14="", "", MAX($A$1:B13) +1) -> 7 | C14: 病历名称 | J14: chistory_name | R14: varchar | W14: 100 | AA14: ●
A15: =IF(C15="", "", MAX($A$1:B14) +1) -> 8 | C15: 患者姓名 | J15: patient_name | R15: varchar | W15: 50 | AA15: ●
A16: =IF(C16="", "", MAX($A$1:B15) +1) -> 9 | C16: 性别 | J16: patient_sex | R16: tinyint | W16: 1
A17: =IF(C17="", "", MAX($A$1:B16) +1) -> 10 | C17: 出生日期 | J17: birthday | R17: date
A18: =IF(C18="", "", MAX($A$1:B17) +1) -> 11 | C18: 家庭住址 | J18: home_address | R18: varchar | W18: 255
A19: =IF(C19="", "", MAX($A$1:B18) +1) -> 12 | C19: 身份证件 | J19: passports | R19: varchar | W19: 255
A20: =IF(C20="", "", MAX($A$1:B19) +1) -> 13 | C20: 疾病种类 | J20: disease_id | R20: int | AF20: m_disease | AJ20: disease_id
A21: =IF(C21="", "", MAX($A$1:B20) +1) -> 14 | C21: 远程会诊想要解决的具体问题 | J21: want_resolve_problem | R21: text
A22: =IF(C22="", "", MAX($A$1:B21) +1) -> 15 | C22: 已知的过敏药物 | J22: sensitive_medicine | R22: text
A23: =IF(C23="", "", MAX($A$1:B22) +1) -> 16 | C23: 吸烟，饮酒史 | J23: smoking_drinking | R23: text
A24: =IF(C24="", "", MAX($A$1:B23) +1) -> 17 | C24: 长期的慢性疾病 | J24: chronic_disease | R24: text
A25: =IF(C25="", "", MAX($A$1:B24) +1) -> 18 | C25: 相关的家族病史 | J25: family_disease | R25: text
A26: =IF(C26="", "", MAX($A$1:B25) +1) -> 19 | C26: 其它补充 | J26: note | R26: text
A27: =IF(C27="", "", MAX($A$1:B26) +1)
A28: =IF(C28="", "", MAX($A$1:B27) +1)
A29: =IF(C29="", "", MAX($A$1:B28) +1)
A30: =IF(C30="", "", MAX($A$1:B29) +1)
A31: =IF(C31="", "", MAX($A$1:B30) +1)
A32: =IF(C32="", "", MAX($A$1:B31) +1)
A33: =IF(C33="", "", MAX($A$1:B32) +1) -> 20 | C33: 创建时刻 | J33: create_time | R33: timestamp | AA33: ●
A34: =IF(C34="", "", MAX($A$1:B33) +1) -> 21 | C34: 创建人员 | J34: create_user_id | R34: bigint
A35: =IF(C35="", "", MAX($A$1:B34) +1) -> 22 | C35: 修改时刻 | J35: update_time | R35: timestamp
A36: =IF(C36="", "", MAX($A$1:B35) +1) -> 23 | C36: 修改人员 | J36: update_user_id | R36: bigint
A37: =IF(C37="", "", MAX($A$1:B36) +1) -> 24 | C37: 删除标志 | J37: del_flag | R37: int | W37: 1 | Z37: I | AA37: ● | AC37: 0 | AN37: 0: 未删除，1：删除

Sheet 病历附加文件
A1: 表格 | H1: 系统名称 | P1: =标题!C18 -> 3QC全球远程医疗会诊系统 | AK1: 作成日期 | AN1: 43179 | AR1: 作成人员 | AU1: 权
H2: 文档名称 | P2: =标题!J19 -> 数据库设计 | AK2: 修改日期 | AR2: 修改人员 | AU2: 权
H3: 论理表格名称 | P3: 病历附加文件表格 | AK3: 主键 | AR3: 外键
H4: 物理表格名称 | P4: t_cattach | AK4: 维护用
A6: No. | C6: 字段名称 | J6: 英文字段名称 | R6: 类型 | W6: 大小 | Y6: 主键 | Z6: 索引 | AA6: 必须 | AC6: 初始值 | AF6: 外键 | AN6: 备注
AF7: 表格名称 | AJ7: 英文字段名称
A8: =IF(C8="", "", MAX($A$1:B7) +1) -> 1 | C8: 编号 | J8: cattach_id | R8: bigint | Y8: 1 | AA8: ● | AN8: 自动递增
A9: =IF(C9="", "", MAX($A$1:B8) +1) -> 2 | C9: 病历编号 | J9: chistory_id | R9: bigint | AA9: ● | AF9: t_chistory | AJ9: chistory_id
A10: =IF(C10="", "", MAX($A$1:B9) +1) -> 3 | C10: 病历模板编号 | J10: dtemplate_id | R10: int | AA10: ● | AF10: m_dtemplate | AJ10: dtemplate_id
A11: =IF(C11="", "", MAX($A$1:B10) +1) -> 4 | C11: 附加文件 | J11: files | R11: text | AN11: 如果是复数文件，与","组合
A12: =IF(C12="", "", MAX($A$1:B11) +1)
A13: =IF(C13="", "", MAX($A$1:B12) +1)
A14: =IF(C14="", "", MAX($A$1:B13) +1)
A15: =IF(C15="", "", MAX($A$1:B14) +1)
A16: =IF(C16="", "", MAX($A$1:B15) +1)
A17: =IF(C17="", "", MAX($A$1:B16) +1)
A18: =IF(C18="", "", MAX($A$1:B17) +1)
A19: =IF(C19="", "", MAX($A$1:B18) +1)
A20: =IF(C20="", "", MAX($A$1:B19) +1)
A21: =IF(C21="", "", MAX($A$1:B20) +1)
A22: =IF(C22="", "", MAX($A$1:B21) +1)
A23: =IF(C23="", "", MAX($A$1:B22) +1)
... A32: =IF(C32="", "", MAX($A$1:B31) +1)
A33: =IF(C33="", "", MAX($A$1:B32) +1) -> 5 | C33: 创建时刻 | J33: create_time | R33: timestamp | AA33: ●
A34: =IF(C34="", "", MAX($A$1:B33) +1) -> 6 | C34: 创建人员 | J34: create_user_id | R34: bigint
A35: =IF(C35="", "", MAX($A$1:B34) +1) -> 7 | C35: 修改时刻 | J35: update_time | R35: timestamp
A36: =IF(C36="", "", MAX($A$1:B35) +1) -> 8 | C36: 修改人员 | J36: update_user_id | R36: bigint
A37: =IF(C37="", "", MAX($A$1:B36) +1) -> 9 | C37: 删除标志 | J37: del_flag | R37: int | W37: 1 | Z37: I | AA37: ● | AC37: 0 | AN37: 0: 未删除，1：删除

Sheet 会诊
A1: 表格 | H1: 系统名称 | P1: =标题!C18 -> 3QC全球远程医疗会诊系统 | AK1: 作成日期 | AN1: 43179 | AR1: 作成人员 | AU1: 权
H2: 文档名称 | P2: =标题!J19 -> 数据库设计 | AK2: 修改日期 | AR2: 修改人员 | AU2: 权
H3: 论理表格名称 | P3: 会诊表格 | AK3: 主键 | AR3: 外键
H4: 物理表格名称 | P4: t_interview | AK4: 维护用
A6: No. | C6: 字段名称 | J6: 英文字段名称 | R6: 类型 | W6: 大小 | Y6: 主键 | Z6: 索引 | AA6: 必须 | AC6: 初始值 | AF6: 外键 | AN6: 备注
AF7: 表格名称 | AJ7: 英文字段名称
A8: =IF(C8="", "", MAX($A$1:B7) +1) -> 1 | C8: 编号 | J8: interview_id | R8: bigint | Y8: 1 | AA8: ●
A9: =IF(C9="", "", MAX($A$1:B8) +1) -> 2 | C9: 患者编号 | J9: patient_id | R9: bigint | Z9: I | AA9: ● | AF9: m_user | AJ9: user_id
A10: =IF(C10="", "", MAX($A$1:B9) +1) -> 3 | C10: 专家编号 | J10: doctor_id | R10: bigint | AF10: m_user | AJ10: user_id
A11: =IF(C11="", "", MAX($A$1:B10) +1) -> 4 | C11: 翻译编号 | J11: interpreter_id | R11: bigint | Z11: I | AF11: m_user | AJ11: user_id
A12: =IF(C12="", "", MAX($A$1:B11) +1) -> 5 | C12: 会诊开始预定时刻 | J12: reserved_starttime | R12: timestamp | Z12: I | AA12: ●
A13: =IF(C13="", "", MAX($A$1:B12) +1) -> 6 | C13: 会诊完毕预定时刻 | J13: reserved_endtime | R13: timestamp
A14: =IF(C14="", "", MAX($A$1:B13) +1) -> 7 | C14: 原版病历编号 | J14: chistory_id | R14: bigint | AF14: t_chistory | AJ14: chistory_id
A15: =IF(C15="", "", MAX($A$1:B14) +1) -> 8 | C15: 翻译版病历编号 | J15: trans_chistory_id | R15: bigint | AF15: t_chistory | AJ15: chistory_id
A16: =IF(C16="", "", MAX($A$1:B15) +1) -> 9 | C16: 患者精通语言 | J16: planguage_id | R16: int | AF16: m_language | AJ16: language_id
A17: =IF(C17="", "", MAX($A$1:B16) +1) -> 10 | C17: 专家精通语言 | J17: dlanguage_id | R17: int | AF17: m_language | AJ17: language_id
A18: =IF(C18="", "", MAX($A$1:B17) +1) -> 11 | C18: 是否需要翻译 | J18: need_interpreter | R18: tinyint | W18: 1 | Z18: I | AN18: 0:不需要 1：需要
A19: =IF(C19="", "", MAX($A$1:B18) +1) -> 12 | C19: 状态 | J19: status | R19: decimal | W19: 2 | Z19: I | AA19: ● | AN19: 0：待付款 1：待预约 2：已付款 4：已生效 6：进行中 7：未完成 8：已完成 10：已失效
A20: =IF(C20="", "", MAX($A$1:B19) +1) -> 13 | C20: 部分状态 | J20: sub_status | R20: int | AN20: 1：专家是否接受患者 8：会诊前提醒 64：支付前取消 128：无翻译接单,短信通知管理员
A21: =IF(C21="", "", MAX($A$1:B20) +1) -> 14 | C21: 取消原因 | J21: cancel_cause_id | R21: tinyint | W21: 4
A22: =IF(C22="", "", MAX($A$1:B21) +1) -> 15 | C22: 取消原因详细 | J22: cancel_cause_note | R22: text
A23: =IF(C23="", "", MAX($A$1:B22) +1) -> 16 | C23: 拒绝理由 | J23: reject_cause_id | R23: tinyint | W23: 4
A24: =IF(C24="", "", MAX($A$1:B23) +1) -> 17 | C24: 拒绝理由详细 | J24: reject_cause_note | R24: text
A25: =IF(C25="", "", MAX($A$1:B24) +1) -> 18 | C25: 会诊开始时刻 | J25: interview_starttime | R25: timestamp
A26: =IF(C26="", "", MAX($A$1:B25) +1) -> 19 | C26: 会诊完毕时刻 | J26: interview_endtime | R26: timestamp
A27: =IF(C27="", "", MAX($A$1:B26) +1) -> 20 | C27: 会诊时长 | J27: interview_seconds | R27: int
A28: =IF(C28="", "", MAX($A$1:B27) +1) -> 21 | C28: 患者上线状态 | J28: patient_status | R28: tinyint | W28: 1
A29: =IF(C29="", "", MAX($A$1:B28) +1) -> 22 | C29: 患者开始时刻 | J29: patient_starttime | R29: timestamp
A30: =IF(C30="", "", MAX($A$1:B29) +1) -> 23 | C30: 患者掉线时刻 | J30: patient_leavetime | R30: timestamp
A31: =IF(C31="", "", MAX($A$1:B30) +1) -> 24 | C31: 患者IP | J31: patient_ip | R31: varchar | W31: 15
A32: =IF(C32="", "", MAX($A$1:B31) +1) -> 25 | C32: 专家上线状态 | J32: doctor_status | R32: tinyint | W32: 1
A33: =IF(C33="", "", MAX($A$1:B32) +1) -> 26 | C33: 专家开始时刻 | J33: doctor_starttime | R33: timestamp
A34: =IF(C34="", "", MAX($A$1:B33) +1) -> 27 | C34: 专家掉线时刻 | J34: doctor_leavetime | R34: timestamp
A35: =IF(C35="", "", MAX($A$1:B34) +1) -> 28 | C35: 专家IP | J35: doctor_ip | R35: varchar | W35: 15
A36: =IF(C36="", "", MAX($A$1:B35) +1) -> 29 | C36: 翻译上线状态 | J36: interpreter_status | R36: tinyint | W36: 1
A37: =IF(C37="", "", MAX($A$1:B36) +1) -> 30 | C37: 翻译开始时刻 | J37: interpreter_starttime | R37: timestamp
A38: =IF(C38="", "", MAX($A$1:B37) +1) -> 31 | C38: 翻译掉线时刻 | J38: interpreter_leavetime | R38: timestamp
A39: =IF(C39="", "", MAX($A$1:B38) +1) -> 32 | C39: 翻译IP | J39: interpreter_ip | R39: varchar | W39: 15
A40: =IF(C40="", "", MAX($A$1:B39) +1) -> 33 | C40: 会诊费 | J40: cost | R40: decimal | W40: 10,2
A41: =IF(C41="", "", MAX($A$1:B40) +1) -> 34 | C41: 专家费 | J41: d_cost | R41: decimal | W41: 10,2
...

Sheet 会诊翻译
A1: 表格 | H1: 系统名称 | P1: =标题!C18 -> 3QC全球远程医疗会诊系统 | AK1: 作成日期 | AN1: 43179 | AR1: 作成人员 | AU1: 权
H2: 文档名称 | P2: =标题!J19 -> 数据库设计 | AK2: 修改日期 | AR2: 修改人员 | AU2: 权
H3: 论理表格名称 | P3: 会诊翻译表格 | AK3: 主键 | AR3: 外键
H4: 物理表格名称 | P4: t_interp | AK4: 维护用
A6: No. | C6: 字段名称 | J6: 英文字段名称 | R6: 类型 | W6: 大小 | Y6: 主键 | Z6: 索引 | AA6: 必须 | AC6: 初始值 | AF6: 外键 | AN6: 备注
AF7: 表格名称 | AJ7: 英文字段名称
A8: =IF(C8="", "", MAX($A$1:B7) +1) -> 1 | C8: 编号 | J8: interp_id | R8: int | Y8: 1 | AA8: ● | AN8: 自动递增
A9: =IF(C9="", "", MAX($A$1:B8) +1) -> 2 | C9: 会诊编号 | J9: interview_id | R9: bigint | Z9: I | AF9: m_interview | AJ9: interview_id
A10: =IF(C10="", "", MAX($A$1:B9) +1) -> 3 | C10: 患者精通语言编号 | J10: planguage_id | R10: int | Z10: I | AF10: m_language | AJ10: language_id
A11: =IF(C11="", "", MAX($A$1:B10) +1) -> 4 | C11: 专家精通语言编号 | J11: dlanguage_id | R11: int | Z11: I | AF11: m_language | AJ11: language_id
A12: =IF(C12="", "", MAX($A$1:B11) +1)
A13: =IF(C13="", "", MAX($A$1:B12) +1)
A14: =IF(C14="", "", MAX($A$1:B13) +1)
A15: =IF(C15="", "", MAX($A$1:B14) +1)
A16: =IF(C16="", "", MAX($A$1:B15) +1)
A17: =IF(C17="", "", MAX($A$1:B16) +1)
A18: =IF(C18="", "", MAX($A$1:B17) +1)
A19: =IF(C19="", "", MAX($A$1:B18) +1)
A20: =IF(C20="", "", MAX($A$1:B19) +1)
A21: =IF(C21="", "", MAX($A$1:B20) +1)
A22: =IF(C22="", "", MAX($A$1:B21) +1)
A23: =IF(C23="", "", MAX($A$1:B22) +1)
... A32: =IF(C32="", "", MAX($A$1:B31) +1)
A33: =IF(C33="", "", MAX($A$1:B32) +1) -> 5 | C33: 创建时刻 | J33: create_time | R33: timestamp | AA33: ●
A34: =IF(C34="", "", MAX($A$1:B33) +1) -> 6 | C34: 修改时刻 | J34: update_time | R34: timestamp
A35: =IF(C35="", "", MAX($A$1:B34) +1) -> 7 | C35: 删除标志 | J35: del_flag | R35: int | W35: 1 | Z35: I | AA35: ● | AC35: 0 | AN35: 0: 未删除，1：删除

Sheet 会诊讨论
A1: 表格 | H1: 系统名称 | P1: =标题!C18 -> 3QC全球远程医疗会诊系统 | AK1: 作成日期 | AN1: 43179 | AR1: 作成人员 | AU1: 权
H2: 文档名称 | P2: =标题!J19 -> 数据库设计 | AK2: 修改日期 | AR2: 修改人员 | AU2: 权
H3: 论理表格名称 | P3: 会诊讨论表格 | AK3: 主键 | AR3: 外键
H4: 物理表格名称 | P4: t_imessage | AK4: 维护用
A6: No. | C6: 字段名称 | J6: 英文字段名称 | R6: 类型 | W6: 大小 | Y6: 主键 | Z6: 索引 | AA6: 必须 | AC6: 初始值 | AF6: 外键 | AN6: 备注
AF7: 表格名称 | AJ7: 英文字段名称
A8: =IF(C8="", "", MAX($A$1:B7) +1) -> 1 | C8: 编号 | J8: imessage_id | R8: int | Y8: 1 | AA8: ● | AN8: 自动递增
A9: =IF(C9="", "", MAX($A$1:B8) +1) -> 2 | C9: 会诊编号 | J9: interview_id | R9: bigint | Z9: I | AF9: m_interview | AJ9: interview_id
A10: =IF(C10="", "", MAX($A$1:B9) +1) -> 3 | C10: 用户编号 | J10: user_id | R10: int | Z10: I | AF10: m_user | AJ10: user_id
A11: =IF(C11="", "", MAX($A$1:B10) +1) -> 4 | C11: 用户类型 | J11: user_type | R11: int
A12: =IF(C12="", "", MAX($A$1:B11) +1) -> 5 | C12: 讨论内容 | J12: content | R12: text
A13: =IF(C13="", "", MAX($A$1:B12) +1) -> 6 | C13: 阅读标志 | J13: read_flag | R13: int
A14: =IF(C14="", "", MAX($A$1:B13) +1) -> 7 | C14: 内部判别码 | J14: no | R14: varchar | W14: 10
A15: =IF(C15="", "", MAX($A$1:B14) +1)
A16: =IF(C16="", "", MAX($A$1:B15) +1)
A17: =IF(C17="", "", MAX($A$1:B16) +1)
A18: =IF(C18="", "", MAX($A$1:B17) +1)
A19: =IF(C19="", "", MAX($A$1:B18) +1)
A20: =IF(C20="", "", MAX($A$1:B19) +1)
A21: =IF(C21="", "", MAX($A$1:B20) +1)
A22: =IF(C22="", "", MAX($A$1:B21) +1)
A23: =IF(C23="", "", MAX($A$1:B22) +1)
A24: =IF(C24="", "", MAX($A$1:B23) +1)
A25: =IF(C25="", "", MAX($A$1:B24) +1)
A26: =IF(C26="", "", MAX($A$1:B25) +1)
... A32: =IF(C32="", "", MAX($A$1:B31) +1)
A33: =IF(C33="", "", MAX($A$1:B32) +1) -> 8 | C33: 创建时刻 | J33: create_time | R33: timestamp | AA33: ●
A34: =IF(C34="", "", MAX($A$1:B33) +1) -> 9 | C34: 修改时刻 | J34: update_time | R34: timestamp

Sheet 注册用户
A1: 表格 | H1: 系统名称 | P1: =标题!C18 -> 3QC全球远程医疗会诊系统 | AK1: 作成日期 | AN1: 43179 | AR1: 作成人员 | AU1: 权
H2: 文档名称 | P2: =标题!J19 -> 数据库设计 | AK2: 修改日期 | AR2: 修改人员 | AU2: 权
H3: 论理表格名称 | P3: 注册用户表格 | AK3: 主键 | AR3: 外键
H4: 物理表格名称 | P4: t_reguser | AK4: 维护用
A6: No. | C6: 字段名称 | J6: 英文字段名称 | R6: 类型 | W6: 大小 | Y6: 主键 | Z6: 索引 | AA6: 必须 | AC6: 初始值 | AF6: 外键 | AN6: 备注
AF7: 表格名称 | AJ7: 英文字段名称
A8: =IF(C8="", "", MAX($A$1:B7) +1) -> 1 | C8: 编号 | J8: reguser_id | R8: bigint | Y8: 1 | AA8: ●
A9: =IF(C9="", "", MAX($A$1:B8) +1) -> 2 | C9: 姓名 | J9: user_name | R9: varchar | W9: 50 | AA9: ●
A10: =IF(C10="", "", MAX($A$1:B9) +1) -> 3 | C10: 用户类型 | J10: user_type | R10: decimal | W10: 2 | Z10: I | AA10: ● | AN10: 16：患者，32：专家，64：翻译人员
A11: =IF(C11="", "", MAX($A$1:B10) +1) -> 4 | C11: 密码 | J11: password | R11: varchar | W11: 40 | AA11: ● | AN11: SHA1散列
A12: =IF(C12="", "", MAX($A$1:B11) +1) -> 5 | C12: 国家编号 | J12: country_id | R12: int | AF12: m_country | AJ12: country_id
A13: =IF(C13="", "", MAX($A$1:B12) +1) -> 6 | C13: 性别 | J13: sex | R13: decimal | W13: 1 | AN13: 0：男 1：女
A14: =IF(C14="", "", MAX($A$1:B13) +1) -> 7 | C14: 电子邮箱 | J14: email | R14: varchar | W14: 80
A15: =IF(C15="", "", MAX($A$1:B14) +1) -> 8 | C15: 手机号码 | J15: mobile | R15: varchar | W15: 25 | AA15: ●
A16: =IF(C16="", "", MAX($A$1:B15) +1) -> 9 | C16: 紧急联系方式 | J16: other_tel | R16: varchar | W16: 25
A17: =IF(C17="", "", MAX($A$1:B16) +1) -> 10 | C17: 家庭住址 | J17: home_address | R17: varchar | W17: 255
A18: =IF(C18="", "", MAX($A$1:B17) +1) -> 11 | C18: 简介 | J18: introduction | R18: varchar | W18: 511
A19: =IF(C19="", "", MAX($A$1:B18) +1) -> 12 | C19: 专家-职称 | J19: d_title | R19: varchar | W19: 255
A20: =IF(C20="", "", MAX($A$1:B19) +1) -> 13 | C20: 专家-所属科室 | J20: d_depart | R20: varchar | W20: 255
A21: =IF(C21="", "", MAX($A$1:B20) +1) -> 14 | C21: 专家-所属医院编号 | J21: hospitals | R21: varchar | W21: 255 | AN21: 可多选
A22: =IF(C22="", "", MAX($A$1:B21) +1) -> 15 | C22: 专家-会诊费 | J22: d_fee | R22: decimal | W22: 10,2
A23: =IF(C23="", "", MAX($A$1:B22) +1) -> 16 | C23: 专家-会诊费货币单位 | J23: d_cunit | R23: varchar | W23: 3 | AN23: rmb：人民币 usd：美元
A24: =IF(C24="", "", MAX($A$1:B23) +1) -> 17 | C24: 翻译人员-译龄 | J24: i_age | R24: int
A25: =IF(C25="", "", MAX($A$1:B24) +1) -> 18 | C25: 资格证书 | J25: diplomas | R25: varchar | W25: 255
A26: =IF(C26="", "", MAX($A$1:B25) +1) -> 19 | C26: 身份证件 | J26: passports | R26: varchar | W26: 255
A27: =IF(C27="", "", MAX($A$1:B26) +1) -> 20 | C27: 精通语言 | J27: languages | R27: text | AN27: 可多选
A28: =IF(C28="", "", MAX($A$1:B27) +1) -> 21 | C28: 疾病专长 | J28: diseases | R28: text | AN28: 可多选
A29: =IF(C29="", "", MAX($A$1:B28) +1) -> 22 | C29: 审核状态 | J29: status | R29: tinyint | W29: 1 | AN29: 0：未通过 1：通过
A30: =IF(C30="", "", MAX($A$1:B29) +1) -> 23 | C30: 未通过原因 | J30: reject_note | R30: varchar | W30: 255
A31: =IF(C31="", "", MAX($A$1:B30) +1)
A32: =IF(C32="", "", MAX($A$1:B31) +1)
A33: =IF(C33="", "", MAX($A$1:B32) +1)
A34: =IF(C34="", "", MAX($A$1:B33) +1)
A35: =IF(C35="", "", MAX($A$1:B34) +1)
A36: =IF(C36="", "", MAX($A$1:B35) +1)
A37: =IF(C37="", "", MAX($A$1:B36) +1)
A38: =IF(C38="", "", MAX($A$1:B37) +1)
A39: =IF(C39="", "", MAX($A$1:B38) +1)
A40: =IF(C40="", "", MAX($A$1:B39) +1) -> 24 | C40: 创建时刻 | J40: create_time | R40: timestamp | AA40: ●
A41: =IF(C41="", "", MAX($A$1:B40) +1) -> 25 | C41: 创建人员 | J41: create_user_id | R41: bigint
...

Sheet 专家时间
A1: 表格 | H1: 系统名称 | P1: =标题!C18 -> 3QC全球远程医疗会诊系统 | AK1: 作成日期 | AN1: 43179 | AR1: 作成人员 | AU1: 权
H2: 文档名称 | P2: =标题!J19 -> 数据库设计 | AK2: 修改日期 | AR2: 修改人员 | AU2: 权
H3: 论理表格名称 | P3: 专家时间表格 | AK3: 主键 | AR3: 外键
H4: 物理表格名称 | P4: t_dtime | AK4: 维护用
A6: No. | C6: 字段名称 | J6: 英文字段名称 | R6: 类型 | W6: 大小 | Y6: 主键 | Z6: 索引 | AA6: 必须 | AC6: 初始值 | AF6: 外键 | AN6: 备注
AF7: 表格名称 | AJ7: 英文字段名称
A8: =IF(C8="", "", MAX($A$1:B7) +1) -> 1 | C8: 编号 | J8: dtime_id | R8: int | Y8: 1 | AA8: ● | AN8: 自动递增
A9: =IF(C9="", "", MAX($A$1:B8) +1) -> 2 | C9: 专家编号 | J9: doctor_id | R9: bigint | Z9: I | AF9: m_user | AJ9: user_id
A10: =IF(C10="", "", MAX($A$1:B9) +1) -> 3 | C10: 开始时刻 | J10: start_time | R10: timestamp | Z10: I
A11: =IF(C11="", "", MAX($A$1:B10) +1) -> 4 | C11: 状态 | J11: state | R11: int | AN11: 1:预约可能
A12: =IF(C12="", "", MAX($A$1:B11) +1)
A13: =IF(C13="", "", MAX($A$1:B12) +1)
A14: =IF(C14="", "", MAX($A$1:B13) +1)
A15: =IF(C15="", "", MAX($A$1:B14) +1)
A16: =IF(C16="", "", MAX($A$1:B15) +1)
A17: =IF(C17="", "", MAX($A$1:B16) +1)
A18: =IF(C18="", "", MAX($A$1:B17) +1)
A19: =IF(C19="", "", MAX($A$1:B18) +1)
A20: =IF(C20="", "", MAX($A$1:B19) +1)
A21: =IF(C21="", "", MAX($A$1:B20) +1)
A22: =IF(C22="", "", MAX($A$1:B21) +1)
A23: =IF(C23="", "", MAX($A$1:B22) +1)
... A32: =IF(C32="", "", MAX($A$1:B31) +1)
A33: =IF(C33="", "", MAX($A$1:B32) +1) -> 5 | C33: 创建时刻 | J33: create_time | R33: timestamp | AA33: ●
A34: =IF(C34="", "", MAX($A$1:B33) +1) -> 6 | C34: 创建人员 | J34: create_user_id | R34: bigint
A35: =IF(C35="", "", MAX($A$1:B34) +1) -> 7 | C35: 修改时刻 | J35: update_time | R35: timestamp
A36: =IF(C36="", "", MAX($A$1:B35) +1) -> 8 | C36: 修改人员 | J36: update_user_id | R36: bigint

Sheet 反馈
A1: 表格 | H1: 系统名称 | P1: =标题!C18 -> 3QC全球远程医疗会诊系统 | AK1: 作成日期 | AN1: 43179 | AR1: 作成人员 | AU1: 权
H2: 文档名称 | P2: =标题!J19 -> 数据库设计 | AK2: 修改日期 | AR2: 修改人员 | AU2: 权
H3: 论理表格名称 | P3: 反馈表格 | AK3: 主键 | AR3: 外键
H4: 物理表格名称 | P4: t_feedback | AK4: 维护用
A6: No. | C6: 字段名称 | J6: 英文字段名称 | R6: 类型 | W6: 大小 | Y6: 主键 | Z6: 索引 | AA6: 必须 | AC6: 初始值 | AF6: 外键 | AN6: 备注
AF7: 表格名称 | AJ7: 英文字段名称
A8: =IF(C8="", "", MAX($A$1:B7) +1) -> 1 | C8: 编号 | J8: feedback_id | R8: bigint | Y8: 1 | AA8: ●
A9: =IF(C9="", "", MAX($A$1:B8) +1) -> 2 | C9: 用户编号 | J9: user_id | R9: bigint | AF9: m_user | AJ9: user_id
A10: =IF(C10="", "", MAX($A$1:B9) +1) -> 3 | C10: 用户类型 | J10: user_type | R10: int
A11: =IF(C11="", "", MAX($A$1:B10) +1) -> 4 | C11: 手机号码 | J11: mobile | R11: varchar | W11: 20
A12: =IF(C12="", "", MAX($A$1:B11) +1) -> 5 | C12: 电子邮箱 | J12: email | R12: varchar | W12: 80
A13: =IF(C13="", "", MAX($A$1:B12) +1) -> 6 | C13: 反馈内容 | J13: comment | R13: mediumtext
A14: =IF(C14="", "", MAX($A$1:B13) +1) -> 7 | C14: 阅读状态 | J14: status | R14: tinyint | W14: 1
A15: =IF(C15="", "", MAX($A$1:B14) +1)
A16: =IF(C16="", "", MAX($A$1:B15) +1)
A17: =IF(C17="", "", MAX($A$1:B16) +1)
A18: =IF(C18="", "", MAX($A$1:B17) +1)
A19: =IF(C19="", "", MAX($A$1:B18) +1)
A20: =IF(C20="", "", MAX($A$1:B19) +1)
A21: =IF(C21="", "", MAX($A$1:B20) +1)
A22: =IF(C22="", "", MAX($A$1:B21) +1)
A23: =IF(C23="", "", MAX($A$1:B22) +1)
A24: =IF(C24="", "", MAX($A$1:B23) +1)
A25: =IF(C25="", "", MAX($A$1:B24) +1)
A26: =IF(C26="", "", MAX($A$1:B25) +1)
... A39: =IF(C39="", "", MAX($A$1:B38) +1)
A40: =IF(C40="", "", MAX($A$1:B39) +1) -> 8 | C40: 创建时刻 | J40: create_time | R40: timestamp | AA40: ●
A41: =IF(C41="", "", MAX($A$1:B40) +1) -> 9 | C41: 创建人员 | J41: create_user_id | R41: bigint
A42: =IF(C42="", "", MAX($A$1:B41) +1) -> 10 | C42: 修改时刻 | J42: update_time | R42: timestamp
A43: =IF(C43="", "", MAX($A$1:B42) +1) -> 11 | C43: 修改人员 | J43: update_user_id | R43: bigint
A44: =IF(C44="", "", MAX($A$1:B43) +1) -> 12 | C44: 删除标志 | J44: del_flag | R44: int | W44: 1 | Z44: I | AA44: ● | AC44: 0 | AN44: 0: 未删除，1：删除

Sheet 通知
A1: 表格 | H1: 系统名称 | P1: =标题!C18 -> 3QC全球远程医疗会诊系统 | AK1: 作成日期 | AN1: 43179 | AR1: 作成人员 | AU1: 权
H2: 文档名称 | P2: =标题!J19 -> 数据库设计 | AK2: 修改日期 | AR2: 修改人员 | AU2: 权
H3: 论理表格名称 | P3: 通知表格 | AK3: 主键 | AR3: 外键
H4: 物理表格名称 | P4: t_message | AK4: 维护用
A6: No. | C6: 字段名称 | J6: 英文字段名称 | R6: 类型 | W6: 大小 | Y6: 主键 | Z6: 索引 | AA6: 必须 | AC6: 初始值 | AF6: 外键 | AN6: 备注
AF7: 表格名称 | AJ7: 英文字段名称
A8: =IF(C8="", "", MAX($A$1:B7) +1) -> 1 | C8: 编号 | J8: message_id | R8: bigint | Y8: 1 | AA8: ●
A9: =IF(C9="", "", MAX($A$1:B8) +1) -> 2 | C9: 手机号码 | J9: mobile | R9: varchar | W9: 25
A10: =IF(C10="", "", MAX($A$1:B9) +1) -> 3 | C10: 电子邮箱 | J10: email | R10: varchar | W10: 80
A11: =IF(C11="", "", MAX($A$1:B10) +1) -> 4 | C11: 收件人姓名 | J11: email_to_name | R11: varchar | W11: 50
A12: =IF(C12="", "", MAX($A$1:B11) +1) -> 5 | C12: 发件人名称 | J12: email_from_name | R12: varchar | W12: 50
A13: =IF(C13="", "", MAX($A$1:B12) +1) -> 6 | C13: 内容 | J13: content | R13: text
A14: =IF(C14="", "", MAX($A$1:B13) +1) -> 7 | C14: 邮件题目 | J14: email_title | R14: varchar | W14: 100
A15: =IF(C15="", "", MAX($A$1:B14) +1) -> 8 | C15: 邮件头题 | J15: email_header | R15: varchar | W15: 100
A16: =IF(C16="", "", MAX($A$1:B15) +1) -> 9 | C16: 短信头题 | J16: sms_header | R16: varchar | W16: 50
A17: =IF(C17="", "", MAX($A$1:B16) +1) -> 10 | C17: 送信时刻 | J17: send_time | R17: timestamp
A18: =IF(C18="", "", MAX($A$1:B17) +1)
A19: =IF(C19="", "", MAX($A$1:B18) +1)
A20: =IF(C20="", "", MAX($A$1:B19) +1)
A21: =IF(C21="", "", MAX($A$1:B20) +1)
A22: =IF(C22="", "", MAX($A$1:B21) +1)
A23: =IF(C23="", "", MAX($A$1:B22) +1)
A24: =IF(C24="", "", MAX($A$1:B23) +1)
A25: =IF(C25="", "", MAX($A$1:B24) +1)
A26: =IF(C26="", "", MAX($A$1:B25) +1)
A27: =IF(C27="", "", MAX($A$1:B26) +1)
A28: =IF(C28="", "", MAX($A$1:B27) +1)
A29: =IF(C29="", "", MAX($A$1:B28) +1)
... A39: =IF(C39="", "", MAX($A$1:B38) +1)
A40: =IF(C40="", "", MAX($A$1:B39) +1) -> 11 | C40: 创建时刻 | J40: create_time | R40: timestamp | AA40: ●
A41: =IF(C41="", "", MAX($A$1:B40) +1) -> 12 | C41: 修改时刻 | J41: update_time | R41: timestamp

Sheet 补丁
A1: 表格 | H1: 系统名称 | P1: =标题!C18 -> 3QC全球远程医疗会诊系统 | AK1: 作成日期 | AN1: 43179 | AR1: 作成人员 | AU1: 权
H2: 文档名称 | P2: =标题!J19 -> 数据库设计 | AK2: 修改日期 | AR2: 修改人员 | AU2: 权
H3: 论理表格名称 | P3: 补丁表格 | AK3: 主键 | AR3: 外键
H4: 物理表格名称 | P4: t_patch | AK4: 维护用
A6: No. | C6: 字段名称 | J6: 英文字段名称 | R6: 类型 | W6: 大小 | Y6: 主键 | Z6: 索引 | AA6: 必须 | AC6: 初始值 | AF6: 外键 | AN6: 备注
AF7: 表格名称 | AJ7: 英文字段名称
A8: =IF(C8="", "", MAX($A$1:B7) +1) -> 1 | C8: 编号 | J8: patch_id | R8: bigint | Y8: 1 | AA8: ● | AN8: 自动递增
A9: =IF(C9="", "", MAX($A$1:B8) +1) -> 2 | C9: 版本 | J9: version | R9: varchar | W9: 10
A10: =IF(C10="", "", MAX($A$1:B9) +1) -> 3 | C10: 更新详情 | J10: description | R10: varchar | W10: 255
A11: =IF(C11="", "", MAX($A$1:B10) +1)
A12: =IF(C12="", "", MAX($A$1:B11) +1)
A13: =IF(C13="", "", MAX($A$1:B12) +1)
A14: =IF(C14="", "", MAX($A$1:B13) +1)
A15: =IF(C15="", "", MAX($A$1:B14) +1)
A16: =IF(C16="", "", MAX($A$1:B15) +1)
A17: =IF(C17="", "", MAX($A$1:B16) +1)
A18: =IF(C18="", "", MAX($A$1:B17) +1)
A19: =IF(C19="", "", MAX($A$1:B18) +1)
A20: =IF(C20="", "", MAX($A$1:B19) +1)
A21: =IF(C21="", "", MAX($A$1:B20) +1)
A22: =IF(C22="", "", MAX($A$1:B21) +1)
... A39: =IF(C39="", "", MAX($A$1:B38) +1)
A40: =IF(C40="", "", MAX($A$1:B39) +1) -> 4 | C40: 创建时刻 | J40: create_time | R40: timestamp | AA40: ●
A41: =IF(C41="", "", MAX($A$1:B40) +1) -> 5 | C41: 修改时刻 | J41: update_time | R41: timestamp
A42: =IF(C42="", "", MAX($A$1:B41) +1) -> 6 | C42: 删除标志 | J42: del_flag | R42: int | W42: 1 | Z42: I | AA42: ● | AC42: 0 | AN42: 0: 未删除，1：删除

Sheet 录像补丁
A1: 表格 | H1: 系统名称 | P1: =标题!C18 -> 3QC全球远程医疗会诊系统 | AK1: 作成日期 | AN1: 43179 | AR1: 作成人员 | AU1: 权
H2: 文档名称 | P2: =标题!J19 -> 数据库设计 | AK2: 修改日期 | AR2: 修改人员 | AU2: 权
H3: 论理表格名称 | P3: 录像补丁表格 | AK3: 主键 | AR3: 外键
H4: 物理表格名称 | P4: t_patch_record | AK4: 维护用
A6: No. | C6: 字段名称 | J6: 英文字段名称 | R6: 类型 | W6: 大小 | Y6: 主键 | Z6: 索引 | AA6: 必须 | AC6: 初始值 | AF6: 外键 | AN6: 备注
AF7: 表格名称 | AJ7: 英文字段名称
A8: =IF(C8="", "", MAX($A$1:B7) +1) -> 1 | C8: 编号 | J8: patch_id | R8: bigint | Y8: 1 | AA8: ● | AN8: 自动递增
A9: =IF(C9="", "", MAX($A$1:B8) +1) -> 2 | C9: 版本 | J9: version | R9: varchar | W9: 10
A10: =IF(C10="", "", MAX($A$1:B9) +1) -> 3 | C10: 更新详情 | J10: description | R10: varchar | W10: 255
A11: =IF(C11="", "", MAX($A$1:B10) +1)
A12: =IF(C12="", "", MAX($A$1:B11) +1)
A13: =IF(C13="", "", MAX($A$1:B12) +1)
A14: =IF(C14="", "", MAX($A$1:B13) +1)
A15: =IF(C15="", "", MAX($A$1:B14) +1)
A16: =IF(C16="", "", MAX($A$1:B15) +1)
A17: =IF(C17="", "", MAX($A$1:B16) +1)
A18: =IF(C18="", "", MAX($A$1:B17) +1)
A19: =IF(C19="", "", MAX($A$1:B18) +1)
A20: =IF(C20="", "", MAX($A$1:B19) +1)
A21: =IF(C21="", "", MAX($A$1:B20) +1)
A22: =IF(C22="", "", MAX($A$1:B21) +1)
... A39: =IF(C39="", "", MAX($A$1:B38) +1)
A40: =IF(C40="", "", MAX($A$1:B39) +1) -> 4 | C40: 创建时刻 | J40: create_time | R40: timestamp | AA40: ●
A41: =IF(C41="", "", MAX($A$1:B40) +1) -> 5 | C41: 修改时刻 | J41: update_time | R41: timestamp
A42: =IF(C42="", "", MAX($A$1:B41) +1) -> 6 | C42: 删除标志 | J42: del_flag | R42: int | W42: 1 | Z42: I | AA42: ● | AC42: 0 | AN42: 0: 未删除，1：删除

Sheet 访问
A1: 表格 | H1: 系统名称 | P1: =标题!C18 -> 3QC全球远程医疗会诊系统 | AK1: 作成日期 | AN1: 43179 | AR1: 作成人员 | AU1: 权
H2: 文档名称 | P2: =标题!J19 -> 数据库设计 | AK2: 修改日期 | AR2: 修改人员 | AU2: 权
H3: 论理表格名称 | P3: 访问日志表格 | AK3: 主键 | AR3: 外键
H4: 物理表格名称 | P4: l_access | AK4: 维护用
A6: No. | C6: 字段名称 | J6: 英文字段名称 | R6: 类型 | W6: 大小 | Y6: 主键 | Z6: 索引 | AA6: 必须 | AC6: 初始值 | AF6: 外键 | AN6: 备注
AF7: 表格名称 | AJ7: 英文字段名称
A8: =IF(C8="", "", MAX($A$1:B7) +1) -> 1 | C8: 编号 | J8: access_id | R8: bigint | Y8: 1 | AA8: ●
A9: =IF(C9="", "", MAX($A$1:B8) +1) -> 2 | C9: 用户编号 | J9: user_id | R9: bigint | AF9: m_user | AJ9: user_id
A10: =IF(C10="", "", MAX($A$1:B9) +1) -> 3 | C10: 手机号码 | J10: mobile | R10: varchar | W10: 20
A11: =IF(C11="", "", MAX($A$1:B10) +1) -> 4 | C11: 登录时刻 | J11: login_time | R11: timestamp
A12: =IF(C12="", "", MAX($A$1:B11) +1) -> 5 | C12: 访问时刻 | J12: access_time | R12: timestamp
A13: =IF(C13="", "", MAX($A$1:B12) +1)
A14: =IF(C14="", "", MAX($A$1:B13) +1)
A15: =IF(C15="", "", MAX($A$1:B14) +1)
A16: =IF(C16="", "", MAX($A$1:B15) +1)
A17: =IF(C17="", "", MAX($A$1:B16) +1)
A18: =IF(C18="", "", MAX($A$1:B17) +1)
A19: =IF(C19="", "", MAX($A$1:B18) +1)
A20: =IF(C20="", "", MAX($A$1:B19) +1)
A21: =IF(C21="", "", MAX($A$1:B20) +1)
A22: =IF(C22="", "", MAX($A$1:B21) +1)
A23: =IF(C23="", "", MAX($A$1:B22) +1)
A24: =IF(C24="", "", MAX($A$1:B23) +1)
... A39: =IF(C39="", "", MAX($A$1:B38) +1)
A40: =IF(C40="", "", MAX($A$1:B39) +1) -> 6 | C40: 创建时刻 | J40: create_time | R40: timestamp | AA40: ●
A41: =IF(C41="", "", MAX($A$1:B40) +1) -> 7 | C41: 修改时刻 | J41: update_time | R41: timestamp

Sheet 订单跟踪
A1: 表格 | H1: 系统名称 | P1: =标题!C18 -> 3QC全球远程医疗会诊系统 | AK1: 作成日期 | AN1: 43179 | AR1: 作成人员 | AU1: 权
H2: 文档名称 | P2: =标题!J19 -> 数据库设计 | AK2: 修改日期 | AR2: 修改人员 | AU2: 权
H3: 论理表格名称 | P3: 订单跟踪日志表格 | AK3: 主键 | AR3: 外键
H4: 物理表格名称 | P4: l_ihistory | AK4: 维护用
A6: No. | C6: 字段名称 | J6: 英文字段名称 | R6: 类型 | W6: 大小 | Y6: 主键 | Z6: 索引 | AA6: 必须 | AC6: 初始值 | AF6: 外键 | AN6: 备注
AF7: 表格名称 | AJ7: 英文字段名称
A8: =IF(C8="", "", MAX($A$1:B7) +1) -> 1 | C8: 编号 | J8: ihistory_id | R8: bigint | Y8: 1 | AA8: ● | AN8: 自动递增
A9: =IF(C9="", "", MAX($A$1:B8) +1) -> 2 | C9: 会诊编号 | J9: interview_id | R9: bigint | Z9: I | AF9: m_interview | AJ9: interview_id
A10: =IF(C10="", "", MAX($A$1:B9) +1) -> 3 | C10: 跟踪类型 | J10: ihistory_type | R10: int
A11: =IF(C11="", "", MAX($A$1:B10) +1) -> 4 | C11: 数据1 | J11: data1 | R11: text
A12: =IF(C12="", "", MAX($A$1:B11) +1) -> 5 | C12: 数据2 | J12: data2 | R12: text
A13: =IF(C13="", "", MAX($A$1:B12) +1) -> 6 | C13: 数据3 | J13: data3 | R13: text
A14: =IF(C14="", "", MAX($A$1:B13) +1) -> 7 | C14: 数据4 | J14: data4 | R14: text | AN14: 跟踪类型详细
A15: =IF(C15="", "", MAX($A$1:B14) +1) | AN15: 0 : 预约会诊
A16: =IF(C16="", "", MAX($A$1:B15) +1) | AN16: 1 : 会诊费变更为xxx
A17: =IF(C17="", "", MAX($A$1:B16) +1) | AN17: 2 : 30分钟内未付款
A18: =IF(C18="", "", MAX($A$1:B17) +1) | AN18: 3 : 银联/PayPal成功支付
A19: =IF(C19="", "", MAX($A$1:B18) +1) | AN19: 4 : 翻译接单
A20: =IF(C20="", "", MAX($A$1:B19) +1) | AN20: 5 : 指派翻译
A21: =IF(C21="", "", MAX($A$1:B20) +1) | AN21: 6 : 专家已查看病历
A22: =IF(C22="", "", MAX($A$1:B21) +1) | AN22: 7 : 开始会诊
A23: =IF(C23="", "", MAX($A$1:B22) +1) | AN23: 8 : 结束会诊
A24: =IF(C24="", "", MAX($A$1:B23) +1) | AN24: 9 : 专家上传诊疗方案
